Workbook

Sheet Import
A1: Skogsstyrelsen
M20: Fördelnig trsl
M21: Tall | N21: Gran | O21: Löv
M22: 1.7 | N22: 2.3 | O22: 2.7
L23: Förd. Tim/mav | P23: Dec | Q23: Barr | R23: Löv
L24: Tim | M24: =M22*P24 -> 0.39187859 | N24: =N22*P24 -> 0.53018868 | P24: =Q24/(Q24+Q25) -> 0.23051682 | Q24: 1124
L25: Mav barr | M25: =M22*P25 -> 1.3081214 | N25: =N22*P25 -> 1.7698113 | P25: =Q25/(Q24+Q25) -> 0.76948318 | Q25: 3752
L26: Mav löv | O26: =O22 -> 2.7 | R26: 1676

Sheet Heatingpl

Sheet P&P
A1: Åtgångstal (Jimmy) | B1: Mekanisk | C1: 2.4 | D1: =1/C1 -> 0.41666667 | E1: Gran | I1: Åtgångstal | J1: Mekanisk | K1: 2.4875622 | L1: =1/K1 -> 0.402 | M1: Gran | AC1: Summa
B2: Halvkemisk | C2: 2.3 | D2: =1/C2 -> 0.43478261 | E2: Löv | I2: The Nordic Forest Sector Model (NFSM): Data and Model Structure | J2: Halvkemisk | K2: 2.6666667 | L2: =1/K2 -> 0.375 | M2: Gran | AD2: Biometria | AE2: Skogsind.
B3: Sulfat | C3: 4.7 | D3: =1/C3 -> 0.21276596 | E3: Gran | F3: Tall | G3: Löv | J3: Sulfat | K3: 4.5454545 | L3: =1/K3 -> 0.22 | M3: Gran | N3: Tall | O3: Löv | Q3: https | R3: //www.biometria.se/media/iktlg5wt/skogsindustrins-virkesfoerbrukning-och-produktion-2019.pdf | AC3: Mek + halvmek | AD3: =2996+214 -> 3210 | AE3: 3000
B4: Sulfit | C4: 4.7 | D4: =1/C4 -> 0.21276596 | E4: Gran | F4: Tall | J4: Sulfit | K4: 6.25 | L4: =1/K4 -> 0.16 | M4: Gran | N4: Tall | O4: Löv | Q4: sista kolumnen medel 15-19 | AC4: Kemisk | AD4: =500+8280 -> 8780 | AE4: 9000
B5: Dissolving | C5: 4.7 | D5: =1/C5 -> 0.21276596 | E5: Löv | J5: Dissolving | K5: 6.25 | L5: =1/K5 -> 0.16 | M5: Gran | N5: Tall | O5: Löv | AC5: Summa | AD5: =SUM(AD3:AD4) -> 11990 | AE5: =SUM(AE3:AE4) -> 12000
I7: Main use | J7: Recovered paper quality | K7: ASH/Filler content (%) | L7: SweFor number | AC7: Supply skogsind.
A8: Mechanical pulp, energy | B8: MWh/bdt | C8: -2.45 | I8: Newsprint | J8: ONP | K8: 3-15 | L8: 0.1 | AC8: Newsprint (1000 t y-1) | AD8: 900
I9: Magazines and commercial adds | J9: OMG | K9: 25-35 | L9: 0.3 | AC9: Other chem. (1000 t y-1) | AD9: =2400+400 -> 2800
I10: Packaging | J10: OCC | K10: 5-15 | L10: 0.1 | AC10: Other mech. (1000 t y-1)
A11: Onarheim, K., Santos, S., Kangas, P., & Hankalin, V. (2017). | I11: Computer print-outs | J11: MOW | K11: 15-35 | L11: 0.3 | AC11: Packaging (1000 t y-1) | AD11: =(2.9+2.1+0.9)*1000 -> 5900
A12: Kraft mill | C12: adt/m3 | I12: Tissue paper | K12: 5 | L12: 0.05 | Q12: https | R12: //www.skogsindustrierna.se/om-skogsindustrin/branschstatistik/ | AC12: Chem. pulp (1000 t y-1) | AD12: =900+3400 -> 4300
A13: M3 per adt | B13: 5.8 | C13: =1/B13 -> 0.17241379 | AC13: Dissolving pulp (1000 t y-1)
A14: Conventional (MWh/adt) | B14: 1.127 | AC14: Mech. pulp (1000 t y-1) | AD14: 400
A15: BECSS (MWh/adt) | B15: 0.22 | I15: Från skogsstatistisk årsbok 2014 | AC15: Summa | AD15: =SUM(AD8:AD14) -> 14300
A16: Integrated pulp and board mill | I16: sulfit/fat | J16: =1/4.8 -> 0.20833333 | AC16: Sawn wood (mill. m3sw y-1) | AD16: 18.4
A17: M3 per adt | B17: =5.8/(0.5+0.23) -> 7.9452055 | C17: =1/B17 -> 0.12586207 | I17: diss | J17: =J16 -> 0.20833333
A18: Conventional (MWh/adt) | B18: 0.66 | I18: mech | J18: =1/2.4 -> 0.41666667
A19: M3 per adt BECss | B19: =(5.8+0.13)/(0.5+0.23) -> 8.1232877 | C19: =1/B19 -> 0.12310287 | I19: halv | J19: =1/2.3 -> 0.43478261
A20: BECSS (MWh/adt) | B20: 0.22
A22: MWh per tonTS (16.8 GJ of heating value per dry ton) | B22: 4.67
F25: Unit | H25: ElP&P
A26: Energy use | B26: External electricity (bought) | F26: GJ/ton | G26: MWh/ton | H26: MWh/ton
A27: Chemical Pulping | B27: Sulphate pulp, bleached, dried | F27: 0.4 | G27: =F27*0.28 -> 0.112 | H27: ='ElP&P'!M5 -> -0.036272879
A28: Chemical Pulping | B28: Sulphate pulp, unbleached, dried | F28: 0.9 | G28: =F28*0.28 -> 0.252 | H28: ?
A29: Mechanical Pulping | B29: Thermo‐ mechanical pulp, dried | F29: 4.3 | G29: =F29*0.28 -> 1.204 | H29: ='ElP&P'!M3 -> 1.7595745
A30: Other Pulping | B30: Recycled paper, slush | F30: 1.3 | G30: =F30*0.28 -> 0.364 | H30: -
A31: Paper Making | B31: Newsprint | F31: 2.1 | G31: =F31*0.28 -> 0.588
A32: Paper Making | B32: Kraft paper‐ board | F32: 1.5 | G32: =F32*0.28 -> 0.42

Sheet CostAnalysis
I1: Analysis costs | J1: Sawmpi | K1: Sawmsp | L1: Sawmal | M1: Heatpl | N1: CHPpl_ | O1: FTDpl_ | P1: PuChem | Q1: PuCTMP | R1: PuMech | S1: PuDiss | T1: PaChem | U1: OtChem | V1: OtMech | W1: NwMech | X1: PuBCCS | Y1: PaBCCS | Z1: OtBCCS | AA1: TerFTD | AB1: TerTsp | AC1: TerTal | AD1: TerPsp | AE1: TerPal | AF1: TerHea | AI1: Profit analysis model | AJ1: Sawnwd | AK1: Heat__ | AL1: Electr | AM1: PuChem | AN1: PuMech | AO1: PuDiss | AP1: PaChem | AQ1: OtChem | AR1: OtMech | AS1: NwMech | AU1: Branschnyckeltal efter näringsgren SNI 2007, storleksklass, kvartil, tabellinnehåll och år | BH1: Ivestment miodels
A2: Heating plants | I2: SEK = 10*EUR | J2: /m3sv | K2: /m3sv | L2: /m3sv | M2: /MWh | N2: /MWh | O2: /MWh | P2: /adt | R2: /adt | S2: /adt | T2: /adt | U2: /adt | V2: /adt | W2: /adt | X2: /adt | Y2: /adt | Z2: /adt | AA2: /m3fub | AI2: Price per unit | AJ2: 2152.3304 | AK2: 600 | AL2: 650 | AM2: 5671.6872 | AN2: 4521.8223 | AO2: 7543.8623 | AP2: 7987.3416 | AQ2: 8979.0978 | AR2: 6194.7449 | AS2: 5203.8885 | BH2: NorFor | BI2: Works quite well. Necessitates 2 stp procedure.
A3: Capital cost, CHP | B3: öre/kWh | C3: 11 | D3: kr/MWh | E3: =C3*1000/100*C7 -> 123.2 | I3: Investment | J3: =C23 -> 0 | K3: =J3 -> 0 | L3: =K3 -> 0 | M3: =E10 -> 1284.6312 | N3: =E11 -> 128.46312 | O3: =B218 -> 5087.1906 | P3: =C145*10 -> 16762.5 | Q3: =B119*C81/C82*10 -> 14731.034 | R3: =B119*C79/C82*10 -> 6444.8276 | S3: =C$145*10 -> 16762.5 | T3: =D145*10-P3 -> 4751.0135 | U3: =T3 -> 4751.0135 | V3: =W3 -> 3068.9655 | W3: =B119*10-Q3 -> 3068.9655 | X3: 1 | Y3: 1 | Z3: 1 | AA3: 1 | AB3: 1 | AC3: 1 | AD3: 1 | AE3: 1 | AF3: 1 | AI3: ./. Capital cost | AJ3: =-PPMT(0.03,1,20,J3,0) -> 0 | AK3: =-PPMT(0.03,1,20,K3,0) -> 0 | AM3: =-PPMT(0.03,1,20,P3,0) -> 623.8283 | AN3: =-PPMT(0.03,1,20,Q3,0) -> 548.22587 | AO3: =-PPMT(0.03,1,20,S3,0) -> 623.8283 | AP3: =-PPMT(0.03,1,20,T3,0) -> 176.81233 | AQ3: =-PPMT(0.03,1,20,U3,0) -> 176.81233 | AR3: =-PPMT(0.03,1,20,V3,0) -> 114.21372 | AS3: =-PPMT(0.03,1,20,W3,0) -> 114.21372 | BA3: Avkastning på totalt kapital (procent) | BB3: Rörelsemarginal (procent) | BC3: Nettomarginal (procent) | BD3: Bruttovinstmarginal (procent) | BE3: Vinstprocent (procent) | BH3: The simple model with no depreciation | BI3: Wokr well but tends to give more activity in the bgeginning. Theroretical basis?
A4: Operating cost, CHP | B4: öre/kWh | C4: 20 | D4: kr/MWh | E4: =C4*1000/100*C7 -> 224 | I4: Variable cost | J4: =C24 -> 0 | K4: =J4 -> 0 | L4: =K4 -> 0 | M4: =E6 -> 168 | N4: =E4 -> 224 | O4: =B219 -> 625.67561 | P4: =C$147*10 -> 860 | Q4: =P4 -> 860 | R4: =Q4 -> 860 | S4: =C$147*10 -> 860 | T4: =D147*10-P4 -> 180 | U4: =T4 -> 180 | V4: =W4 -> 180 | W4: =T4 -> 180 | X4: 1 | Y4: 1 | Z4: 1 | AA4: 0 | AB4: 0 | AC4: 0 | AD4: 0 | AE4: 0 | AF4: 0 | AI4: ./. Variable cost | AJ4: =J4 -> 0 | AK4: =M4 -> 168 | AM4: =P4 -> 860 | AN4: =Q4 -> 860 | AO4: =S4 -> 860 | AP4: =T4+AM4 -> 1040 | AQ4: =U4+AM4 -> 1040 | AR4: =V4+AN4 -> 1040 | AS4: =W4+AN4 -> 1040 | BA4: 2019 | BB4: 2019 | BC4: 2019 | BD4: 2019 | BE4: 2019 | BH4: Depreciation and evaluating with investment value * df(4) | BI4: Too expnsive - no activity until second half of horizon
A5: Capital cost, heating | B5: öre/kWh | C5: 10 | D5: kr/MWh | E5: =C5*1000/100*C7 -> 112 | I5: Fixed cost | J5: =C25 -> 0 | K5: =J5 -> 0 | L5: =K5 -> 0 | M5: 0 | N5: 0 | O5: 0 | P5: =C$146*10 -> 650 | Q5: =Q3*Q7 -> 736.55172 | R5: =Q5 -> 736.55172 | S5: =C$146*10 -> 650 | T5: =D146*10-S5 -> 250 | U5: =T5 -> 250 | V5: =W5 -> 153.44828 | W5: =W3*W7 -> 153.44828 | X5: 1 | Y5: 1 | Z5: 1 | AA5: 0 | AB5: 0 | AC5: 0 | AD5: 0 | AE5: 0 | AF5: 0 | AI5: ./. Fixed cost | AJ5: =J5 -> 0 | AK5: =M5 -> 0 | AM5: =P5 -> 650 | AN5: =Q5 -> 736.55172 | AO5: =S5 -> 650 | AP5: =T5+AM5 -> 900 | AQ5: =U5+AM5 -> 900 | AR5: =V5+AN5 -> 890 | AS5: =W5+AN5 -> 890 | AU5: 16.1 | AV5: Sågverk och hyvlerier | AW5: +50 | AX5: minst 50 anställda | AY5: Med | AZ5: median | BA5: 8.2 | BB5: 5.2 | BC5: 5.1 | BD5: .. | BE5: 5.3 | BH5: Assume age structure of capacity and replacement after depr. Time
A6: Operating cost, heating | B6: öre/kWh | C6: 15 | D6: kr/MWh | E6: =C6*1000/100*C7 -> 168 | I6: Depreciation period | J6: 20 | K6: 20 | L6: 20 | M6: 20 | N6: 20 | O6: 20 | P6: 20 | Q6: 20 | R6: 20 | S6: 20 | T6: 20 | U6: 20 | V6: 20 | W6: 20 | X6: 20 | Y6: 20 | Z6: 20 | AA6: 999 | AB6: 999 | AC6: 999 | AD6: 999 | AE6: 999 | AF6: 999 | AI6: ./. Wood cost | AJ6: =AJ13/#REF! -> #REF! | AK6: =AJ15/4.8 -> 41.666667 | AM6: =AJ14/'P&P'!D3 -> 1803.0516 | AN6: =AJ14/'P&P'!D1 -> 920.7072 | AO6: =AJ14/'P&P'!D5 -> 1803.0516 | AP6: =AM6 -> 1803.0516 | AQ6: =AM6 -> 1803.0516 | AR6: =AJ14/'P&P'!D1 -> 920.7072 | AS6: =AN6 -> 920.7072 | AU6: 16.2 | AV6: Industri för trä och varor av trä, kork och rotting o.d. | AW6: +50 | AX6: minst 50 anställda | AY6: Med | AZ6: median | BA6: 6.1 | BB6: 2.4 | BC6: 2.6 | BD6: .. | BE6: 2.8
A7: KPI 2009-2020 | C7: =336/300 -> 1.12 | E7: =SUM(E5:E6) -> 280 | I7: Maintenance rate | J7: 0.05 | K7: =J7 -> 0.05 | L7: =K7 -> 0.05 | M7: 0.05 | N7: 0.05 | P7: 0 | Q7: 0.05 | S7: 0 | T7: 0 | U7: =T7 -> 0 | V7: =W7 -> 0.05 | W7: 0.05 | X7: =E145*10 -> 5207.5 | Y7: =F145*10 -> 6716.2162 | Z7: =Y7 -> 6716.2162 | AA7: 0 | AB7: 0 | AC7: 0 | AD7: 0 | AE7: 0 | AF7: 0 | AI7: Net | AJ7: =AJ2-SUM(AJ3:AJ6) -> #REF! | AK7: =AK2-SUM(AK3:AK6) -> 390.33333 | AL7: =AL2-SUM(AL3:AL6) -> 650 | AM7: =AM2-SUM(AM3:AM6) -> 1734.8073 | AN7: =AN2-SUM(AN3:AN6) -> 1456.3375 | AO7: =AO2-SUM(AO3:AO6) -> 3606.9824 | AP7: =AP2-SUM(AP3:AP6) -> 4067.4777 | AQ7: =AQ2-SUM(AQ3:AQ6) -> 5059.2338 | ... AS7: =AS2-SUM(AS3:AS6) -> 2238.9676 | AU7: 17.1 | AV7: Massa-, pappers- och pappindustri | AW7: +50 | AX7: minst 50 anställda | AY7: Med | AZ7: median | BA7: 11.2 | BB7: 8.2 | BC7: 8.3 | BD7: .. | BE7: 8.7
A8: Depreciation time | B8: y | C8: 20 | I8: Interest rate for investment | J8: 0.06 | K8: 0.06 | L8: 0.06 | M8: 0.06 | N8: 0.06 | P8: 0.06 | Q8: 0.06 | S8: 0.06 | T8: 0.06 | U8: 0.06 | V8: 0.06 | W8: 0.06 | X8: =E147*10 -> 320 | Y8: =F147*10 -> 480 | Z8: =Y8 -> 480 | AA8: 0 | AB8: 0 | AC8: 0 | AD8: 0 | AE8: 0 | AF8: 0 | AI8: Wood as part of op. Cost | AJ8: =AJ6/SUM(AJ4:AJ6) -> #REF! | AK8: =AK6/SUM(AK4:AK6) -> 0.19872814 | AM8: =AM6/SUM(AM4:AM6) -> 0.54422684 | AN8: =AN6/SUM(AN4:AN6) -> 0.36575785 | AO8: =AO6/SUM(AO4:AO6) -> 0.54422684 | AP8: =AP6/SUM(AP4:AP6) -> 0.48170632 | AQ8: =AQ6/SUM(AQ4:AQ6) -> 0.48170632 | AR8: =AR6/SUM(AR4:AR6) -> 0.32297501 | AS8: =AS6/SUM(AS4:AS6) -> 0.32297501 | AU8: 17.2 | AV8: Industri för pappers- och pappvaror | AW8: +50 | AX8: minst 50 anställda | AY8: Med | AZ8: median | BA8: 6.7 | BB8: 3.7 | BC8: 4.5 | BD8: .. | BE8: 4.8
A9: Calcluating rate | B9: % | C9: 0.06 | I9: Scrap value fraction | J9: 0.05 | K9: 0.05 | L9: 0.05 | M9: 0.05 | N9: 0.05 | P9: 0.05 | Q9: 0.05 | S9: 0.05 | T9: 0.05 | U9: 0.05 | V9: 0.05 | W9: 0.05 | X9: =E146*10 -> 150 | Y9: =F146*10 -> 180 | Z9: =Y9 -> 180 | AA9: 0 | AB9: 0 | AC9: 0 | AD9: 0 | AE9: 0 | AF9: 0 | AI9: Marginal (% på pris) | AJ9: =AJ7/AJ2 -> #REF! | AK9: =AK7/AK2 -> 0.65055556 | AL9: =AL7/AL2 -> 1 | AM9: =AM7/AM2 -> 0.30587148 | AN9: =AN7/AN2 -> 0.32206871 | AO9: =AO7/AO2 -> 0.47813471 | AP9: =AP7/AP2 -> 0.50924048 | AQ9: =AQ7/AQ2 -> 0.56344568 | ... AS9: =AS7/AS2 -> 0.43024895
A10: --> investment cost, heating | B10: öre/kWh | D10: kr/MWh | E10: =-PV(C9,20,E5) -> 1284.6312 | I10: Depreciation factor per y | J10: =J9^(1/J6) -> 0.86089166 | K10: =K9^(1/K6) -> 0.86089166 | L10: =L9^(1/L6) -> 0.86089166 | M10: =M9^(1/M6) -> 0.86089166 | N10: =N9^(1/N6) -> 0.86089166 | P10: =P9^(1/P6) -> 0.86089166 | Q10: =Q9^(1/Q6) -> 0.86089166 | S10: =S9^(1/S6) -> 0.86089166 | T10: =T9^(1/T6) -> 0.86089166 | U10: =U9^(1/U6) -> 0.86089166 | V10: =V9^(1/V6) -> 0.86089166 | W10: =W9^(1/W6) -> 0.86089166 | X10: 0 | Y10: 0 | Z10: 0 | AA10: 0 | AB10: 0 | AC10: 0 | AD10: 0 | AE10: 0 | AF10: 0 | AI10: Förädlingvärde | AJ10: =(AJ2-AJ6) -> #REF! | AK10: =(AK2-AK6) -> 558.33333 | AL10: =(AL2-AL6) -> 650 | AM10: =(AM2-AM6) -> 3868.6356 | AN10: =(AN2-AN6) -> 3601.1151 | AO10: =(AO2-AO6) -> 5740.8107 | AP10: =(AP2-AP6) -> 6184.29 | AQ10: =(AQ2-AQ6) -> 7176.0462 | ... AS10: =(AS2-AS6) -> 4283.1813
A11: --> add investment cost,CHP | B11: öre/kWh | D11: kr/MWh | E11: =-PV(C9,20,E3)-E10 -> 128.46312
A12: Flisning GROT | B12: kr/tonTS | C12: 166 | I12: {=TRANSPOSE(I1:AF10)} -> Analysis costs | J12: SEK = 10*EUR | K12: Investment | L12: Variable cost | M12: Fixed cost | N12: Depreciation period | O12: Maintenance rate | P12: Interest rate for investment | Q12: Scrap value fraction | R12: Depreciation factor per y
A13: Price, CHP | B13: öre/kWh | C13: 65 | E13: =C13*1000/100 -> 650 | I13: Sawmpi | J13: /m3sv | K13: 0 | L13: 0 | M13: 0 | N13: 20 | O13: 0.05 | P13: 0.06 | Q13: 0.05 | R13: 0.86089166 | AI13: Timmerpris | AJ13: =550+(36 + 1.62*90 )*0.46 -> 633.628
A14: Price, heatin | B14: öre/kWh | C14: 60 | E14: =C14*1000/100 -> 600 | I14: Sawmsp | J14: /m3sv | K14: 0 | L14: 0 | M14: 0 | N14: 20 | O14: 0.05 | P14: 0.06 | Q14: 0.05 | R14: 0.86089166 | AI14: Massaved | AJ14: =300+(36 + 1.62*90 )*0.46 -> 383.628
I15: Sawmal | J15: /m3sv | K15: 0 | L15: 0 | M15: 0 | N15: 20 | O15: 0.05 | P15: 0.06 | Q15: 0.05 | R15: 0.86089166 | AI15: GROT | AJ15: 200
I16: Heatpl | J16: /MWh | K16: 1284.6312 | L16: 168 | M16: 0 | N16: 20 | O16: 0.05 | P16: 0.06 | Q16: 0.05 | R16: 0.86089166
I17: CHPpl_ | J17: /MWh | K17: 128.46312 | L17: 224 | M17: 0 | N17: 20 | O17: 0.05 | P17: 0.06 | Q17: 0.05 | R17: 0.86089166
I18: FTDpl_ | J18: /MWh | K18: 5087.1906 | L18: 625.67561 | M18: 0 | N18: 20 | O18: 0 | P18: 0 | Q18: 0 | R18: 0 | AC18: Actual BCCS cost
I19: PuChem | J19: /adt | K19: 16762.5 | L19: 860 | M19: 650 | N19: 20 | O19: 0 | P19: 0.06 | Q19: 0.05 | R19: 0.86089166 | AC19: PuBCCS | AD19: PaBCCS | AE19: OtBCCS
I20: PuCTMP | J20: 0 | K20: 14731.034 | L20: 860 | M20: 736.55172 | N20: 20 | O20: 0.05 | P20: 0.06 | Q20: 0.05 | R20: 0.86089166 | AC20: /adt | AD20: /adt | AE20: /adt
I21: PuMech | J21: /adt | K21: 6444.8276 | L21: 860 | M21: 736.55172 | N21: 20 | O21: 0 | P21: 0 | Q21: 0 | R21: 0
I22: PuDiss | J22: /adt | K22: 16762.5 | L22: 860 | M22: 650 | N22: 20 | O22: 0 | P22: 0.06 | Q22: 0.05 | R22: 0.86089166
I23: PaChem | J23: /adt | K23: 4751.0135 | L23: 180 | M23: 250 | N23: 20 | O23: 0 | P23: 0.06 | Q23: 0.05 | R23: 0.86089166
I24: OtChem | J24: /adt | K24: 4751.0135 | L24: 180 | M24: 250 | N24: 20 | O24: 0 | P24: 0.06 | Q24: 0.05 | R24: 0.86089166
I25: OtMech | J25: /adt | K25: 3068.9655 | L25: 180 | M25: 153.44828 | N25: 20 | O25: 0.05 | P25: 0.06 | Q25: 0.05 | R25: 0.86089166
I26: NwMech | J26: /adt | K26: 3068.9655 | L26: 180 | M26: 153.44828 | N26: 20 | O26: 0.05 | P26: 0.06 | Q26: 0.05 | R26: 0.86089166
I27: PuBCCS | J27: /adt | K27: 1 | L27: 1 | M27: 1 | N27: 20 | O27: 5207.5 | P27: 320 | Q27: 150 | R27: 0
I28: PaBCCS | J28: /adt | K28: 1 | L28: 1 | M28: 1 | N28: 20 | O28: 6716.2162 | P28: 480 | Q28: 180 | R28: 0
I29: OtBCCS | J29: /adt | K29: 1 | L29: 1 | M29: 1 | N29: 20 | O29: 6716.2162 | P29: 480 | Q29: 180 | R29: 0
I30: TerFTD | J30: /m3fub | K30: 1 | L30: 0 | M30: 0 | N30: 999 | O30: 0 | P30: 0 | Q30: 0 | R30: 0
I31: TerTsp | J31: 0 | K31: 1 | L31: 0 | M31: 0 | N31: 999 | O31: 0 | P31: 0 | Q31: 0 | R31: 0
I32: TerTal | J32: 0 | K32: 1 | L32: 0 | M32: 0 | N32: 999 | O32: 0 | P32: 0 | Q32: 0 | R32: 0
I33: TerPsp | J33: 0 | K33: 1 | L33: 0 | M33: 0 | N33: 999 | O33: 0 | P33: 0 | Q33: 0 | R33: 0
I34: TerPal | J34: 0 | K34: 1 | L34: 0 | M34: 0 | N34: 999 | O34: 0 | P34: 0 | Q34: 0 | R34: 0
I35: TerHea | J35: 0 | K35: 1 | L35: 0 | M35: 0 | N35: 999 | O35: 0 | P35: 0 | Q35: 0 | R35: 0
I36: #N/A | J36: #N/A | K36: #N/A | L36: #N/A | M36: #N/A | N36: #N/A | O36: #N/A | P36: #N/A | Q36: #N/A | R36: #N/A
I37: #N/A | J37: #N/A | K37: #N/A | L37: #N/A | M37: #N/A | N37: #N/A | O37: #N/A | P37: #N/A | Q37: #N/A | R37: #N/A
I38: #N/A | J38: #N/A | K38: #N/A | L38: #N/A | M38: #N/A | N38: #N/A | O38: #N/A | P38: #N/A | Q38: #N/A | R38: #N/A
I39: #N/A | J39: #N/A | K39: #N/A | L39: #N/A | M39: #N/A | N39: #N/A | O39: #N/A | P39: #N/A | Q39: #N/A | R39: #N/A
I40: #N/A | J40: #N/A | K40: #N/A | L40: #N/A | M40: #N/A | N40: #N/A | O40: #N/A | P40: #N/A | Q40: #N/A | R40: #N/A
...

Sheet FAOSTAT_data_11-21-2020
A1: Domain Code | B1: Domain | C1: Area Code | D1: Area | E1: Element Code | F1: Element | G1: Item Code | H1: Item | K1: Year Code | L1: Year | M1: Unit | N1: Value | O1: AIMMS final produt | R1: Flag | S1: Flag Description
A2: FO | B2: Forestry Production and Trade | C2: 210 | D2: Sweden | E2: 5516 | F2: Production | G2: 1632 | H2: Sawnwood, coniferous | I2: Price (9 SEK/USD) | J2: =N4/N3*9*1000 -> 2152.3304 | K2: 2019 | L2: 2019 | M2: m3 | N2: 18630000 | O2: Sawnwd | S2: Official data
A3: FO | B3: Forestry Production and Trade | C3: 210 | D3: Sweden | E3: 5916 | F3: Export Quantity | G3: 1632 | H3: Sawnwood, coniferous | I3: Tot Q | J3: =N2 -> 18630000 | K3: 2019 | L3: 2019 | M3: m3 | N3: 12601014 | S3: Official data
A4: FO | B4: Forestry Production and Trade | C4: 210 | D4: Sweden | E4: 5922 | F4: Export Value | G4: 1632 | H4: Sawnwood, coniferous | I4: Export | J4: =N3 -> 12601014 | K4: 2019 | L4: 2019 | M4: 1000 US$ | N4: 3013505 | S4: Official data
A5: FO | B5: Forestry Production and Trade | C5: 210 | D5: Sweden | E5: 5510 | F5: Production | G5: 1685 | H5: Mechanical and semi-chemical wood pulp | I5: Price (9 SEK/USD) | J5: =N7/N6*9*1000 -> 4521.8223 | K5: 2019 | L5: 2019 | M5: tonnes | N5: 3193000 | O5: PuMech | S5: Official data
A6: FO | B6: Forestry Production and Trade | C6: 210 | D6: Sweden | E6: 5910 | F6: Export Quantity | G6: 1685 | H6: Mechanical and semi-chemical wood pulp | I6: Tot Q | J6: =N5 -> 3193000 | K6: 2019 | L6: 2019 | M6: tonnes | N6: 409948 | S6: Official data
A7: FO | B7: Forestry Production and Trade | C7: 210 | D7: Sweden | E7: 5922 | F7: Export Value | G7: 1685 | H7: Mechanical and semi-chemical wood pulp | I7: Export | J7: =N6 -> 409948 | K7: 2019 | L7: 2019 | M7: 1000 US$ | N7: 205968 | S7: Official data
A8: FO | B8: Forestry Production and Trade | C8: 210 | D8: Sweden | E8: 5510 | F8: Production | G8: 1656 | H8: Chemical wood pulp | I8: Price (9 SEK/USD) | J8: =N10/N9*9*1000 -> 5637.7665 | K8: 2019 | L8: 2019 | M8: tonnes | N8: 8398000 | R8: Im | S8: FAO data based on imputation methodology
A9: FO | B9: Forestry Production and Trade | C9: 210 | D9: Sweden | E9: 5910 | F9: Export Quantity | G9: 1656 | H9: Chemical wood pulp | I9: Tot Q | J9: =N8 -> 8398000 | K9: 2019 | L9: 2019 | M9: tonnes | N9: 3486859 | R9: Im | S9: FAO data based on imputation methodology
A10: FO | B10: Forestry Production and Trade | C10: 210 | D10: Sweden | E10: 5922 | F10: Export Value | G10: 1656 | H10: Chemical wood pulp | I10: Export | J10: =N9 -> 3486859 | K10: 2019 | L10: 2019 | M10: 1000 US$ | N10: 2184233 | R10: Im | S10: FAO data based on imputation methodology
A11: FO | B11: Forestry Production and Trade | C11: 210 | D11: Sweden | E11: 5510 | F11: Production | G11: 1662 | H11: Chemical wood pulp, sulphate, unbleached | I11: Price (9 SEK/USD) | J11: =N13/N12*9*1000 -> 5367.4654 | K11: 2019 | L11: 2019 | M11: tonnes | N11: 2780000 | R11: * | S11: Unofficial figure
A12: FO | B12: Forestry Production and Trade | C12: 210 | D12: Sweden | E12: 5910 | F12: Export Quantity | G12: 1662 | H12: Chemical wood pulp, sulphate, unbleached | I12: Tot Q | J12: =N11 -> 2780000 | K12: 2019 | L12: 2019 | M12: tonnes | N12: 171012 | R12: * | S12: Unofficial figure
A13: FO | B13: Forestry Production and Trade | C13: 210 | D13: Sweden | E13: 5922 | F13: Export Value | G13: 1662 | H13: Chemical wood pulp, sulphate, unbleached | I13: Export | J13: =N12 -> 171012 | K13: 2019 | L13: 2019 | M13: 1000 US$ | N13: 101989 | R13: * | S13: Unofficial figure
A14: FO | B14: Forestry Production and Trade | C14: 210 | D14: Sweden | E14: 5510 | F14: Production | G14: 1663 | H14: Chemical wood pulp, sulphate, bleached | I14: Price (9 SEK/USD) | J14: =N16/N15*9*1000 -> 5671.6872 | K14: 2019 | L14: 2019 | M14: tonnes | N14: 5581000 | O14: PuChem | S14: Official data
A15: FO | B15: Forestry Production and Trade | C15: 210 | D15: Sweden | E15: 5910 | F15: Export Quantity | G15: 1663 | H15: Chemical wood pulp, sulphate, bleached | I15: Tot Q | J15: =N14 -> 5581000 | K15: 2019 | L15: 2019 | M15: tonnes | N15: 3290524 | S15: Official data
A16: FO | B16: Forestry Production and Trade | C16: 210 | D16: Sweden | E16: 5922 | F16: Export Value | G16: 1663 | H16: Chemical wood pulp, sulphate, bleached | I16: Export | J16: =N15 -> 3290524 | K16: 2019 | L16: 2019 | M16: 1000 US$ | N16: 2073647 | S16: Official data
A17: FO | B17: Forestry Production and Trade | C17: 210 | D17: Sweden | E17: 5510 | F17: Production | G17: 1686 | H17: Chemical wood pulp, sulphite | I17: Price (9 SEK/USD) | J17: =N19/N18*9*1000 -> 3055.4437 | K17: 2019 | L17: 2019 | M17: tonnes | N17: 37000 | R17: Im | S17: FAO data based on imputation methodology
A18: FO | B18: Forestry Production and Trade | C18: 210 | D18: Sweden | E18: 5910 | F18: Export Quantity | G18: 1686 | H18: Chemical wood pulp, sulphite | I18: Tot Q | J18: =N17 -> 37000 | K18: 2019 | L18: 2019 | M18: tonnes | N18: 25323 | S18: Official data
A19: FO | B19: Forestry Production and Trade | C19: 210 | D19: Sweden | E19: 5922 | F19: Export Value | G19: 1686 | H19: Chemical wood pulp, sulphite | I19: Export | J19: =N18 -> 25323 | K19: 2019 | L19: 2019 | M19: 1000 US$ | N19: 8597 | S19: Official data
A20: FO | B20: Forestry Production and Trade | C20: 210 | D20: Sweden | E20: 5510 | F20: Production | G20: 1667 | H20: Dissolving wood pulp | I20: Price (9 SEK/USD) | J20: =N22/N21*9*1000 -> 7543.8623 | K20: 2019 | L20: 2019 | M20: tonnes | N20: 483000 | O20: PuDiss | R20: Im | S20: FAO data based on imputation methodology
A21: FO | B21: Forestry Production and Trade | C21: 210 | D21: Sweden | E21: 5910 | F21: Export Quantity | G21: 1667 | H21: Dissolving wood pulp | I21: Tot Q | J21: =N20 -> 483000 | K21: 2019 | L21: 2019 | M21: tonnes | N21: 336337 | S21: Official data
A22: FO | B22: Forestry Production and Trade | C22: 210 | D22: Sweden | E22: 5922 | F22: Export Value | G22: 1667 | H22: Dissolving wood pulp | I22: Export | J22: =N21 -> 336337 | K22: 2019 | L22: 2019 | M22: 1000 US$ | N22: 281920 | S22: Official data
A23: FO | B23: Forestry Production and Trade | C23: 210 | D23: Sweden | E23: 5510 | F23: Production | G23: 1671 | H23: Newsprint | I23: Price (9 SEK/USD) | J23: =N25/N24*9*1000 -> 5203.8885 | K23: 2019 | L23: 2019 | M23: tonnes | N23: 889000 | O23: NwMech | S23: Official data
A24: FO | B24: Forestry Production and Trade | C24: 210 | D24: Sweden | E24: 5910 | F24: Export Quantity | G24: 1671 | H24: Newsprint | I24: Tot Q | J24: =N23 -> 889000 | K24: 2019 | L24: 2019 | M24: tonnes | N24: 702124 | S24: Official data
A25: FO | B25: Forestry Production and Trade | C25: 210 | D25: Sweden | E25: 5922 | F25: Export Value | G25: 1671 | H25: Newsprint | I25: Export | J25: =N24 -> 702124 | K25: 2019 | L25: 2019 | M25: 1000 US$ | N25: 405975 | S25: Official data
A26: FO | B26: Forestry Production and Trade | C26: 210 | D26: Sweden | E26: 5510 | F26: Production | G26: 1674 | H26: Printing and writing papers | I26: Price (9 SEK/USD) | J26: =N28/N27*9*1000 -> 6950.2848 | K26: 2019 | L26: 2019 | M26: tonnes | N26: 2365000 | R26: Im | S26: FAO data based on imputation methodology
A27: FO | B27: Forestry Production and Trade | C27: 210 | D27: Sweden | E27: 5910 | F27: Export Quantity | G27: 1674 | H27: Printing and writing papers | I27: Tot Q | J27: =N26 -> 2365000 | K27: 2019 | L27: 2019 | M27: tonnes | N27: 2489140 | R27: Im | S27: FAO data based on imputation methodology
A28: FO | B28: Forestry Production and Trade | C28: 210 | D28: Sweden | E28: 5922 | F28: Export Value | G28: 1674 | H28: Printing and writing papers | I28: Export | J28: =N27 -> 2489140 | K28: 2019 | L28: 2019 | M28: 1000 US$ | N28: 1922248 | R28: Im | S28: FAO data based on imputation methodology
A29: FO | B29: Forestry Production and Trade | C29: 210 | D29: Sweden | E29: 5510 | F29: Production | G29: 1612 | H29: Printing and writing papers, uncoated, mechanical | I29: Price (9 SEK/USD) | J29: =N31/N30*9*1000 -> 6194.7449 | K29: 2019 | L29: 2019 | M29: tonnes | N29: 1292392 | O29: OtMech | R29: F | S29: FAO estimate
A30: FO | B30: Forestry Production and Trade | C30: 210 | D30: Sweden | E30: 5910 | F30: Export Quantity | G30: 1612 | H30: Printing and writing papers, uncoated, mechanical | I30: Tot Q | J30: =N29 -> 1292392 | K30: 2019 | L30: 2019 | M30: tonnes | N30: 1372303 | S30: Official data
A31: FO | B31: Forestry Production and Trade | C31: 210 | D31: Sweden | E31: 5922 | F31: Export Value | G31: 1612 | H31: Printing and writing papers, uncoated, mechanical | I31: Export | J31: =N30 -> 1372303 | K31: 2019 | L31: 2019 | M31: 1000 US$ | N31: 944563 | S31: Official data
A32: FO | B32: Forestry Production and Trade | C32: 210 | D32: Sweden | E32: 5510 | F32: Production | G32: 1615 | H32: Printing and writing papers, uncoated, wood free | I32: Price (9 SEK/USD) | J32: =N34/N33*9*1000 -> 8979.0978 | K32: 2019 | L32: 2019 | M32: tonnes | N32: 457736 | O32: OtChem | R32: F | S32: FAO estimate
A33: FO | B33: Forestry Production and Trade | C33: 210 | D33: Sweden | E33: 5910 | F33: Export Quantity | G33: 1615 | H33: Printing and writing papers, uncoated, wood free | I33: Tot Q | J33: =N32 -> 457736 | K33: 2019 | L33: 2019 | M33: tonnes | N33: 462869 | S33: Official data
A34: FO | B34: Forestry Production and Trade | C34: 210 | D34: Sweden | E34: 5922 | F34: Export Value | G34: 1615 | H34: Printing and writing papers, uncoated, wood free | I34: Export | J34: =N33 -> 462869 | K34: 2019 | L34: 2019 | M34: 1000 US$ | N34: 461794 | S34: Official data
A35: FO | B35: Forestry Production and Trade | C35: 210 | D35: Sweden | E35: 5510 | F35: Production | G35: 1616 | H35: Printing and writing papers, coated | I35: Price (9 SEK/USD) | J35: =N37/N36*9*1000 -> 7099.7648 | K35: 2019 | L35: 2019 | M35: tonnes | N35: 614872 | R35: F | S35: FAO estimate
A36: FO | B36: Forestry Production and Trade | C36: 210 | D36: Sweden | E36: 5910 | F36: Export Quantity | G36: 1616 | H36: Printing and writing papers, coated | I36: Tot Q | J36: =N35 -> 614872 | K36: 2019 | L36: 2019 | M36: tonnes | N36: 653968 | S36: Official data
A37: FO | B37: Forestry Production and Trade | C37: 210 | D37: Sweden | E37: 5922 | F37: Export Value | G37: 1616 | H37: Printing and writing papers, coated | I37: Export | J37: =N36 -> 653968 | K37: 2019 | L37: 2019 | M37: 1000 US$ | N37: 515891 | S37: Official data
A38: FO | B38: Forestry Production and Trade | C38: 210 | D38: Sweden | E38: 5510 | F38: Production | G38: 1675 | H38: Other paper and paperboard | I38: Price (9 SEK/USD) | J38: =N40/N39*9*1000 -> 7987.3416 | K38: 2019 | L38: 2019 | M38: tonnes | N38: 6362000 | O38: PaChem | P38: FAO data based on imputation methodology
A39: FO | B39: Forestry Production and Trade | C39: 210 | D39: Sweden | E39: 5910 | F39: Export Quantity | G39: 1675 | H39: Other paper and paperboard | I39: Tot Q | J39: =N38 -> 6362000 | K39: 2019 | L39: 2019 | M39: tonnes | N39: 6009380 | O39: Im | P39: FAO data based on imputation methodology
A40: FO | B40: Forestry Production and Trade | C40: 210 | D40: Sweden | E40: 5922 | F40: Export Value | G40: 1675 | H40: Other paper and paperboard | I40: Export | J40: =N39 -> 6009380 | K40: 2019 | L40: 2019 | M40: 1000 US$ | N40: 5333219 | O40: Im | P40: FAO data based on imputation methodology
...

Sheet Scenarios
A2: Demand scenario BAU - change of basic
A3: Period | B3: Base Q | C3: 1 | D3: 2 | E3: 3 | F3: 4 | G3: 5 | H3: 6 | I3: 7 | J3: 8 | K3: 9 | L3: 10 | M3: 11 | N3: 12 | O3: 13 | P3: 14 | Q3: 15 | R3: 16 | S3: 17 | T3: 18 | U3: 19 | V3: 20 | W3: 21 | X3: 22 | Y3: 23 | Z3: 24
A4: Length (y) | C4: 5 | D4: 5 | E4: 5 | F4: 5 | G4: 5 | H4: 5 | I4: 5 | J4: 5 | K4: 5 | L4: 5 | M4: 5 | N4: 5 | O4: 5 | P4: 5 | Q4: 5 | R4: 5 | S4: 5 | T4: 5 | U4: 5 | V4: 5 | W4: 5 | X4: 5 | Y4: 5 | Z4: 5
A5: Sawnwd | B5: 18630000 | C5: =B5 -> 18630000 | D5: =C5*(1+ScenAssump!$D$4*D$4) -> 18816300 | E5: =D5*(1+ScenAssump!$D$4*E$4) -> 19004463 | F5: =E5*(1+ScenAssump!$D$4*F$4) -> 19194508 | G5: =F5*(1+ScenAssump!$D$4*G$4) -> 19386453 | H5: =G5*(1+ScenAssump!$D$4*H$4) -> 19580317 | I5: =H5 -> 19580317 | J5: =I5 -> 19580317 | K5: =J5 -> 19580317 | L5: =K5 -> 19580317 | M5: =L5 -> 19580317 | N5: =M5 -> 19580317 | O5: =N5 -> 19580317 | P5: =O5 -> 19580317 | ... Z5: =Y5 -> 19580317
A6: Heat__ | B6: =ScenAssump!B18*1000000 -> 20250000 | C6: =ScenAssump!B18*1000000 -> 20250000 | D6: =ScenAssump!C18*1000000 -> 20250000 | E6: =ScenAssump!D18*1000000 -> 18000000 | F6: =ScenAssump!E18*1000000 -> 18750000 | G6: =ScenAssump!F18*1000000 -> 18000000 | H6: =ScenAssump!G18*1000000 -> 18750000 | I6: =ScenAssump!H18*1000000 -> 17250000 | J6: =I6 -> 17250000 | K6: =J6 -> 17250000 | L6: =K6 -> 17250000 | M6: =L6 -> 17250000 | N6: =M6 -> 17250000 | O6: =N6 -> 17250000 | P6: =O6 -> 17250000 | Q6: =P6 -> 17250000 | ... Z6: =Y6 -> 17250000
A7: Electr | B7: =ScenAssump!B19*1000000 -> 0 | C7: =ScenAssump!B19*1000000 -> 0 | D7: =ScenAssump!C19*1000000 -> 0 | E7: =ScenAssump!D19*1000000 -> 0 | F7: =ScenAssump!E19*1000000 -> 0 | G7: =ScenAssump!F19*1000000 -> 0 | H7: =ScenAssump!G19*1000000 -> 0 | I7: =ScenAssump!H19*1000000 -> 0 | J7: =I7 -> 0 | K7: =J7 -> 0 | L7: =K7 -> 0 | M7: =L7 -> 0 | N7: =M7 -> 0 | O7: =N7 -> 0 | P7: =O7 -> 0 | Q7: =P7 -> 0 | ... Z7: =Y7 -> 0
A8: BioFue | B8: =ScenAssump!B20*1000000 -> 0 | C8: =ScenAssump!B20*1000000 -> 0 | D8: =ScenAssump!C20*1000000 -> 0 | E8: =ScenAssump!D20*1000000 -> 0 | F8: =ScenAssump!E20*1000000 -> 0 | G8: =ScenAssump!F20*1000000 -> 0 | H8: =ScenAssump!G20*1000000 -> 0 | I8: =ScenAssump!H20*1000000 -> 0 | J8: =I8 -> 0 | K8: =J8 -> 0 | L8: =K8 -> 0 | M8: =L8 -> 0 | N8: =M8 -> 0 | O8: =N8 -> 0 | P8: =O8 -> 0 | Q8: =P8 -> 0 | ... Z8: =Y8 -> 0
A9: PuChem | B9: 3290524 | C9: =B9 -> 3290524 | D9: =C9*(1+ScenAssump!$I$7*D$4) -> 3435447.1 | E9: =D9*(1+ScenAssump!$I$7*E$4) -> 3586753 | F9: =E9*(1+ScenAssump!$I$7*F$4) -> 3744722.7 | G9: =F9*(1+ScenAssump!$I$7*G$4) -> 3909649.9 | H9: =G9*(1+ScenAssump!$I$7*H$4) -> 4081840.9 | I9: =H9 -> 4081840.9 | J9: =I9 -> 4081840.9 | K9: =J9 -> 4081840.9 | L9: =K9 -> 4081840.9 | M9: =L9 -> 4081840.9 | N9: =M9 -> 4081840.9 | O9: =N9 -> 4081840.9 | P9: =O9 -> 4081840.9 | ... Z9: =Y9 -> 4081840.9
A10: PuMech | B10: 409948 | C10: =B10 -> 409948 | D10: =C10*(1+ScenAssump!$I$6*D$4) -> 403929.61 | E10: =D10*(1+ScenAssump!$I$6*E$4) -> 397999.58 | F10: =E10*(1+ScenAssump!$I$6*F$4) -> 392156.61 | G10: =F10*(1+ScenAssump!$I$6*G$4) -> 386399.42 | H10: =G10*(1+ScenAssump!$I$6*H$4) -> 380726.74 | I10: =H10 -> 380726.74 | J10: =I10 -> 380726.74 | K10: =J10 -> 380726.74 | L10: =K10 -> 380726.74 | M10: =L10 -> 380726.74 | N10: =M10 -> 380726.74 | O10: =N10 -> 380726.74 | P10: =O10 -> 380726.74 | ... Z10: =Y10 -> 380726.74
A11: PuDiss | B11: 336337 | C11: =B11 -> 336337 | D11: =C11*(1+ScenAssump!$I$7*D$4) -> 351150.14 | E11: =D11*(1+ScenAssump!$I$7*E$4) -> 366615.69 | F11: =E11*(1+ScenAssump!$I$7*F$4) -> 382762.38 | G11: =F11*(1+ScenAssump!$I$7*G$4) -> 399620.22 | H11: =G11*(1+ScenAssump!$I$7*H$4) -> 417220.51 | I11: =H11 -> 417220.51 | J11: =I11 -> 417220.51 | K11: =J11 -> 417220.51 | L11: =K11 -> 417220.51 | M11: =L11 -> 417220.51 | N11: =M11 -> 417220.51 | O11: =N11 -> 417220.51 | P11: =O11 -> 417220.51 | ... Z11: =Y11 -> 417220.51
A12: PaChem | B12: 6362000 | C12: =B12 -> 6362000 | D12: =C12*(1+ScenAssump!$I$7*D$4) -> 6642198.7 | E12: =D12*(1+ScenAssump!$I$7*E$4) -> 6934738.2 | F12: =E12*(1+ScenAssump!$I$7*F$4) -> 7240161.8 | G12: =F12*(1+ScenAssump!$I$7*G$4) -> 7559037 | H12: =G12*(1+ScenAssump!$I$7*H$4) -> 7891956.3 | I12: =H12 -> 7891956.3 | J12: =I12 -> 7891956.3 | K12: =J12 -> 7891956.3 | L12: =K12 -> 7891956.3 | M12: =L12 -> 7891956.3 | N12: =M12 -> 7891956.3 | O12: =N12 -> 7891956.3 | P12: =O12 -> 7891956.3 | ... Z12: =Y12 -> 7891956.3
A13: OtChem | B13: 462869 | C13: =B13 -> 462869 | D13: =C13*(1+ScenAssump!$I$7*D$4) -> 483254.93 | E13: =D13*(1+ScenAssump!$I$7*E$4) -> 504538.72 | F13: =E13*(1+ScenAssump!$I$7*F$4) -> 526759.89 | G13: =F13*(1+ScenAssump!$I$7*G$4) -> 549959.74 | H13: =G13*(1+ScenAssump!$I$7*H$4) -> 574181.38 | I13: =H13 -> 574181.38 | J13: =I13 -> 574181.38 | K13: =J13 -> 574181.38 | L13: =K13 -> 574181.38 | M13: =L13 -> 574181.38 | N13: =M13 -> 574181.38 | O13: =N13 -> 574181.38 | P13: =O13 -> 574181.38 | ... Z13: =Y13 -> 574181.38
A14: OtMech | B14: 1372303 | C14: =B14 -> 1372303 | D14: =C14*(1+ScenAssump!$I$6*D$4) -> 1352156.4 | E14: =D14*(1+ScenAssump!$I$6*E$4) -> 1332305.6 | F14: =E14*(1+ScenAssump!$I$6*F$4) -> 1312746.2 | G14: =F14*(1+ScenAssump!$I$6*G$4) -> 1293474 | H14: =G14*(1+ScenAssump!$I$6*H$4) -> 1274484.7 | I14: =H14 -> 1274484.7 | J14: =I14 -> 1274484.7 | K14: =J14 -> 1274484.7 | L14: =K14 -> 1274484.7 | M14: =L14 -> 1274484.7 | N14: =M14 -> 1274484.7 | O14: =N14 -> 1274484.7 | P14: =O14 -> 1274484.7 | ... Z14: =Y14 -> 1274484.7
A15: NwMech | B15: 889000 | C15: =B15 -> 889000 | D15: =C15*(1+ScenAssump!$I$5*D$4) -> 862897.44 | E15: =D15*(1+ScenAssump!$I$5*E$4) -> 837561.31 | F15: =E15*(1+ScenAssump!$I$5*F$4) -> 812969.08 | G15: =F15*(1+ScenAssump!$I$5*G$4) -> 789098.92 | H15: =G15*(1+ScenAssump!$I$5*H$4) -> 765929.63 | I15: =H15 -> 765929.63 | J15: =I15 -> 765929.63 | K15: =J15 -> 765929.63 | L15: =K15 -> 765929.63 | M15: =L15 -> 765929.63 | N15: =M15 -> 765929.63 | O15: =N15 -> 765929.63 | P15: =O15 -> 765929.63 | ... Z15: =Y15 -> 765929.63
A16: Sum P&P | B16: =SUM(B9:B15) -> 13122981 | C16: =SUM(C9:C15) -> 13122981 | D16: =SUM(D9:D15) -> 13531034 | E16: =SUM(E9:E15) -> 13960512 | F16: =SUM(F9:F15) -> 14412279 | G16: =SUM(G9:G15) -> 14887239 | H16: =SUM(H9:H15) -> 15386340 | I16: =SUM(I9:I15) -> 15386340 | ... Z16: =SUM(Z9:Z15) -> 15386340
A17: Summa tot | B17: =SUM(B5:B15) -> 52002981 | C17: =SUM(C5:C15) -> 52002981 | D17: =SUM(D5:D15) -> 52597334 | E17: =SUM(E5:E15) -> 50964975 | F17: =SUM(F5:F15) -> 52356786 | G17: =SUM(G5:G15) -> 52273692 | H17: =SUM(H5:H15) -> 53716657 | I17: =SUM(I5:I15) -> 52216657 | ... Z17: =SUM(Z5:Z15) -> 52216657
B19: 1 | C19: 3 | D19: 3 | E19: 6 | F19: 6
A20: Profu | B20: 2018 | C20: 2030L | D20: 2030S | E20: 2045L | F20: 2045S
A21: Avlutar | B21: 42 | C21: 54 | D21: 54 | E21: 58 | F21: 58
A22: Biprod | B22: 26 | C22: 28 | D22: 32 | E22: 30 | F22: 35
A23: Stamved | B23: 15 | C23: 23 | D23: 27 | E23: 24 | F23: 30
A24: GROT | B24: 10 | C24: 21 | D24: 37 | E24: 21 | F24: 38
A25: Tallolja mm | B25: 4 | C25: 4 | D25: 4 | E25: 4 | F25: 4
A26: Nya sort (inkl. Stubbar) | B26: 0 | C26: 18 | D26: 20 | E26: 17 | F26: 18
A27: Tot sum | B27: =SUM(B21:B26) -> 97 | C27: =SUM(C21:C26) -> 148 | D27: =SUM(D21:D26) -> 174 | E27: =SUM(E21:E26) -> 154 | F27: =SUM(F21:F26) -> 183
A28: Sum Bip., Stam., GROT, New | B28: =B22+B23+B24+B26 -> 51 | C28: =C22+C23+C24+C26 -> 90 | D28: =D22+D23+D24+D26 -> 116 | E28: =E22+E23+E24+E26 -> 92 | F28: =F22+F23+F24+F26 -> 121
A29: Rel. Increase/5-y | B29: 1 | C29: =1+(C28/B28-1)/2 -> 1.3823529 | D29: =1+(D28/B28-1)/2 -> 1.6372549 | E29: =1+(E28/C28-1)/3 -> 1.0074074 | F29: =1+(F28/D28-1)/3 -> 1.0143678
A31: SWEFOR bas-körning
A32: Biprod | B32: =(6.725+0.327)*0.46*4.8 -> 15.570816
A33: Stamved | B33: =(0.224+0.17)*0.46*4.8 -> 0.869952
A34: GROT | B34: =1.034*4.8 -> 4.9632
A35: Net el. from P&P | B35: =13.162-6.991+0.598 -> 6.769
A36: Sum | B36: =SUM(B32:B35) -> 28.172968

Sheet ScenAssump
A1: SKA22 | L1: Scenario B2
C2: 2020+ | D2: 2050 | F2: Scenario B2 | G2: Structure of historic and projected paper consumption in the EU/EFTA: shares of total paper and paperboard quantity consumed | H2: - | L2: Average annual growth rates in the B2 reference future for the consumption of wood products in Europe by product category, period, and region (EU/EFTA) | O2: 2020-2030
B3: BAU | L3: Sawnwood | O3: 0.005 | P3: <-- Sawnwd
A4: Saw timber | B4: dec/y | C4: 0.002 | D4: 0.002 | G4: Tons 2020 | H4: Annual change | I4: 0.29361704 | J4: <-- Shifter | L4: Wood-based panels | O4: 0.009
A5: Pulpwood | B5: dec/y | C5: =2.9/37.8/15 -> 0.0051146384 | D5: =2.9/37.8/15 -> 0.0051146384 | F5: Newsprint | G5: =Scenarios!B15 -> 889000 | H5: =O7 -> -0.02 | I5: =H5*I$4 -> -0.0058723409 | J5: <-- NwMech | L5: Paper and paperboard | O5: 0.009 | P5: <-- PaChem
A6: Bioenergi | B6: dec/y | C6: 0.004 | D6: 0 | F6: Printing and writing paper | G6: =Scenarios!B13+Scenarios!B14 -> 1835172 | H6: =O8 -> -0.01 | I6: =H6*I$4 -> -0.0029361704 | J6: <-- PuMech; | L6: Structure of historic and projected paper consumption in the EU/EFTA: shares of total paper and paperboard quantity consumed | M6: 2010 | N6: 2030 | O6: Annual change
B7: FS | F7: Other paper and paperboard | G7: =Scenarios!B12 -> 6362000 | H7: =O9 -> 0.03 | I7: =H7*I$4 -> 0.0088085113 | J7: <-- PuChem; PuDiss; OtChem; PaChem | L7: Newsprint | M7: 11.9 | N7: 11.5 | O7: =(N7-M7)/20 -> -0.02 | P7: <-- NwMech
A8: Saw timber | B8: dec/y | C8: 0.002 | G8: =SUM(G5:G7) -> 9086172 | H8: {=MMULT(TRANSPOSE(H5:H7),$G5:$G7)/SUM($G5:$G7)} -> 0.017028984 | I8: {=MMULT(TRANSPOSE(G5:G7),H5:H7)*I4/G8} -> 0.005 | L8: Printing and writing paper | M8: 34.3 | N8: 34.1 | O8: =(N8-M8)/20 -> -0.01 | P8: <-- PuMech;
A9: Pulpwood | B9: dec/y | C9: =2.9/37.8/15 -> 0.0051146384 | L9: Other paper and paperboard | M9: 53.8 | N9: 54.4 | O9: =(N9-M9)/20 -> 0.03 | P9: <-- PuChem; PuDiss; OtChem
A10: Bioenergi | B10: GWh/y | C10: =73/30 -> 2.4333333 | D10: =73/30 -> 2.4333333
B11: IND1
A12: Saw timber | B12: dec/y | C12: 0.01 | D12: 0.01
A13: Pulpwood | B13: dec/y | C13: 0.01 | D13: 0.01
A14: Bioenergi | B14: GWh/y | C14: =73/30 -> 2.4333333 | D14: =73/30 -> 2.4333333
A16: Energy assumptions | B16: =B25 -> 1 | C16: =C25 -> 2 | D16: =D25 -> 3 | E16: =E25 -> 4 | F16: =F25 -> 5 | G16: =G25 -> 6 | H16: =H25 -> 7 | I16: =I25 -> 8+
B17: =B26 -> 2022 | C17: =C26 -> 2027 | D17: =D26 -> 2032 | E17: =E26 -> 2037 | F17: =F26 -> 2042 | G17: =G26 -> 2047 | H17: =H26 -> 2052 | I17: =I26 -> 2057
A18: FV - heat | B18: =B27*0.75 -> 20.25 | C18: =C27*0.75 -> 20.25 | D18: =D27*0.75 -> 18 | E18: =E27*0.75 -> 18.75 | F18: =F27*0.75 -> 18 | G18: =G27*0.75 -> 18.75 | H18: =H27*0.75 -> 17.25 | I18: <-- Assumptions used for the analysis (NB:25% assumed to be garbage)
A19: FV - electricity | B19: 0 | C19: 0 | D19: 0 | E19: 0 | F19: 0 | G19: 0 | H19: 0 | I19: <-- Assumptions used for the analysis
A20: Biofuel | B20: 0 | C20: 0 | D20: 0 | E20: 0 | F20: 0 | G20: 0 | H20: 0 | I20: =I29 -> 0 | J20: <-- Assumptions used for the analysis
A21: Sum | B21: =SUM(B18:B20) -> 20.25 | C21: =SUM(C18:C20) -> 20.25 | D21: =SUM(D18:D20) -> 18 | E21: =SUM(E18:E20) -> 18.75 | F21: =SUM(F18:F20) -> 18 | G21: =SUM(G18:G20) -> 18.75 | H21: =SUM(H18:H20) -> 17.25
A22: Increase | B22: =B21-$B21 -> 0 | C22: =C21-$B21 -> 0 | D22: =D21-$B21 -> -2.25 | E22: =E21-$B21 -> -1.5 | F22: =F21-$B21 -> -2.25 | G22: =G21-$B21 -> -1.5 | H22: =H21-$B21 -> -3
A25: Profu | B25: 1 | C25: 2 | D25: 3 | E25: 4 | F25: 5 | G25: 6 | H25: 7 | I25: 8+
B26: 2022 | C26: =B26+5 -> 2027 | D26: =C26+5 -> 2032 | E26: =D26+5 -> 2037 | F26: =E26+5 -> 2042 | G26: =F26+5 -> 2047 | H26: =G26+5 -> 2052 | I26: =H26+5 -> 2057
A27: FV - heat | B27: 27 | C27: 27 | D27: 24 | E27: 25 | F27: 24 | G27: 25 | H27: 23 | I27: <-- Profu numbers from Olivia 13 sept 2021 (DH incl. electricity)
A28: FV - electricity | B28: 8 | C28: 8 | D28: 8 | E28: 8 | F28: 8 | G28: 8 | H28: 8
A29: Biofuel | B29: 1 | C29: 7 | D29: 20 | E29: 22 | F29: 23 | G29: 25 | H29: 26 | J29: <-- Profu numbers from Göran sep 2022
A30: Sum | B30: =SUM(B27:B29) -> 36 | C30: =SUM(C27:C29) -> 42 | D30: =SUM(D27:D29) -> 52 | E30: =SUM(E27:E29) -> 55 | F30: =SUM(F27:F29) -> 55 | G30: =SUM(G27:G29) -> 58 | H30: =SUM(H27:H29) -> 57
A31: Increase | B31: =B30-$B30 -> 0 | C31: =C30-$B30 -> 6 | D31: =D30-$B30 -> 16 | E31: =E30-$B30 -> 19 | F31: =F30-$B30 -> 19 | G31: =G30-$B30 -> 22 | H31: =H30-$B30 -> 21

Sheet LogFunc
B3: q0 | C3: q | D3: 1/E | E3: A | F3: B | G3: e^-k | H3: k | I3: p0 | J3: k
B4: 18600000 | C4: -1 | D4: =0.01/-C4 -> 0.01 | E4: =0.5*(1+D4) -> 0.505 | F4: =(1-E4)/E4 -> 0.98019802 | G4: =EXP(F4)/EXP((1)) -> 0.98039279 | H4: =LN(G4) -> -0.01980198 | I4: 2152 | J4: =(1-0.01/-C4)/(1+0.01/-C4) -1 -> -0.01980198
C6: q | D6: p | E6: E | F6: ~q | G6: q | H6: E | I6: q
D7: 3873.8237 | I7: =(LN(2*$I$4/D7-1)/-$J$4)*$B$4/100+$B$4 -> -2043956
C8: =C9-500000 -> 1600000 | D8: =2*I$4/(1+EXP(-J$4*((C8-$B$4)/$B$4*100))) -> 3698.6198 | E8: =((C9-C4)/C8)/((D9-D4)/D8) -> 1.3225975 | F8: =LN(2*$I$4/D8-1)/-$H$4 -> -91.397849 | G8: =(F8*$B$4/100+$B$4) -> 1600000 | H8: =((G9-G4)/G8)/((D9-D4)/D8) -> 1.3225962 | I8: =(LN(2*$I$4/D8-1)/-$J$4)*$B$4/100+$B$4 -> 1600000
C9: =C10-500000 -> 2100000 | D9: =2*I$4/(1+EXP(-J$4*((C9-$B$4)/$B$4*100))) -> 3670.3942 | E9: =((C10-C5)/C9)/((D10-D5)/D9) -> 1.2480602 | F9: =LN(2*$I$4/D9-1)/-$H$4 -> -88.709677 | G9: =(F9*$B$4/100+$B$4) -> 2100000 | H9: =((G10-G5)/G9)/((D10-D5)/D9) -> 1.2480602 | I9: =(LN(2*$I$4/D9-1)/-$J$4)*$B$4/100+$B$4 -> 2100000
C10: =C11-500000 -> 2600000 | D10: =2*I$4/(1+EXP(-J$4*((C10-$B$4)/$B$4*100))) -> 3641.0883 | E10: =((C11-C6)/C10)/((D11-D6)/D10) -> #VALUE! | F10: =LN(2*$I$4/D10-1)/-$H$4 -> -86.021505 | G10: =(F10*$B$4/100+$B$4) -> 2600000 | H10: =((G11-G6)/G10)/((D11-D6)/D10) -> #VALUE! | I10: =(LN(2*$I$4/D10-1)/-$J$4)*$B$4/100+$B$4 -> 2600000
C11: =C12-500000 -> 3100000 | D11: =2*I$4/(1+EXP(-J$4*((C11-$B$4)/$B$4*100))) -> 3610.6831 | E11: =((C12-C7)/C11)/((D12-D7)/D11) -> -14.229997 | F11: =LN(2*$I$4/D11-1)/-$H$4 -> -83.333333 | G11: =(F11*$B$4/100+$B$4) -> 3100000 | H11: =((G12-G7)/G11)/((D12-D7)/D11) -> -14.229997 | I11: =(LN(2*$I$4/D11-1)/-$J$4)*$B$4/100+$B$4 -> 3100000
C12: =C13-500000 -> 3600000 | D12: =2*I$4/(1+EXP(-J$4*((C12-$B$4)/$B$4*100))) -> 3579.1609 | E12: =((C13-C11)/C12)/((D13-D11)/D12) -> -15.491723 | F12: =LN(2*$I$4/D12-1)/-$H$4 -> -80.645161 | G12: =(F12*$B$4/100+$B$4) -> 3600000 | H12: =((G13-G11)/G12)/((D13-D11)/D12) -> -15.491723 | I12: =(LN(2*$I$4/D12-1)/-$J$4)*$B$4/100+$B$4 -> 3600000
C13: =C14-500000 -> 4100000 | D13: =2*I$4/(1+EXP(-J$4*((C13-$B$4)/$B$4*100))) -> 3546.5061 | E13: =((C14-C12)/C13)/((D14-D12)/D13) -> -13.016283 | F13: =LN(2*$I$4/D13-1)/-$H$4 -> -77.956989 | G13: =(F13*$B$4/100+$B$4) -> 4100000 | H13: =((G14-G12)/G13)/((D14-D12)/D13) -> -13.016283 | I13: =(LN(2*$I$4/D13-1)/-$J$4)*$B$4/100+$B$4 -> 4100000
C14: =C15-500000 -> 4600000 | D14: =2*I$4/(1+EXP(-J$4*((C14-$B$4)/$B$4*100))) -> 3512.7055 | E14: =((C15-C13)/C14)/((D15-D13)/D14) -> -11.106064 | F14: =LN(2*$I$4/D14-1)/-$H$4 -> -75.268817 | G14: =(F14*$B$4/100+$B$4) -> 4600000 | H14: =((G15-G13)/G14)/((D15-D13)/D14) -> -11.106064 | I14: =(LN(2*$I$4/D14-1)/-$J$4)*$B$4/100+$B$4 -> 4600000
C15: =C16-500000 -> 5100000 | D15: =2*I$4/(1+EXP(-J$4*((C15-$B$4)/$B$4*100))) -> 3477.748 | E15: =((C16-C14)/C15)/((D16-D14)/D15) -> -9.5935584 | F15: =LN(2*$I$4/D15-1)/-$H$4 -> -72.580645 | G15: =(F15*$B$4/100+$B$4) -> 5100000 | H15: =((G16-G14)/G15)/((D16-D14)/D15) -> -9.5935584 | I15: =(LN(2*$I$4/D15-1)/-$J$4)*$B$4/100+$B$4 -> 5100000
C16: =C17-500000 -> 5600000 | D16: =2*I$4/(1+EXP(-J$4*((C16-$B$4)/$B$4*100))) -> 3441.6254 | E16: =((C17-C15)/C16)/((D17-D15)/D16) -> -8.3711415 | F16: =LN(2*$I$4/D16-1)/-$H$4 -> -69.892473 | G16: =(F16*$B$4/100+$B$4) -> 5600000 | H16: =((G17-G15)/G16)/((D17-D15)/D16) -> -8.3711415 | I16: =(LN(2*$I$4/D16-1)/-$J$4)*$B$4/100+$B$4 -> 5600000
C17: =C18-500000 -> 6100000 | D17: =2*I$4/(1+EXP(-J$4*((C17-$B$4)/$B$4*100))) -> 3404.332 | E17: =((C18-C16)/C17)/((D18-D16)/D17) -> -7.3665284 | F17: =LN(2*$I$4/D17-1)/-$H$4 -> -67.204301 | G17: =(F17*$B$4/100+$B$4) -> 6100000 | H17: =((G18-G16)/G17)/((D18-D16)/D17) -> -7.3665284 | I17: =(LN(2*$I$4/D17-1)/-$J$4)*$B$4/100+$B$4 -> 6100000
C18: =C19-500000 -> 6600000 | D18: =2*I$4/(1+EXP(-J$4*((C18-$B$4)/$B$4*100))) -> 3365.8655 | E18: =((C19-C17)/C18)/((D19-D17)/D18) -> -6.5293843 | F18: =LN(2*$I$4/D18-1)/-$H$4 -> -64.516129 | G18: =(F18*$B$4/100+$B$4) -> 6600000 | H18: =((G19-G17)/G18)/((D19-D17)/D18) -> -6.5293843 | I18: =(LN(2*$I$4/D18-1)/-$J$4)*$B$4/100+$B$4 -> 6600000
C19: =C20-500000 -> 7100000 | D19: =2*I$4/(1+EXP(-J$4*((C19-$B$4)/$B$4*100))) -> 3326.2267 | E19: =((C20-C18)/C19)/((D20-D18)/D19) -> -5.8235933 | F19: =LN(2*$I$4/D19-1)/-$H$4 -> -61.827957 | G19: =(F19*$B$4/100+$B$4) -> 7100000 | H19: =((G20-G18)/G19)/((D20-D18)/D19) -> -5.8235933 | I19: =(LN(2*$I$4/D19-1)/-$J$4)*$B$4/100+$B$4 -> 7100000
C20: =C21-500000 -> 7600000 | D20: =2*I$4/(1+EXP(-J$4*((C20-$B$4)/$B$4*100))) -> 3285.4199 | E20: =((C21-C19)/C20)/((D21-D19)/D20) -> -5.2225791 | F20: =LN(2*$I$4/D20-1)/-$H$4 -> -59.139785 | G20: =(F20*$B$4/100+$B$4) -> 7600000 | H20: =((G21-G19)/G20)/((D21-D19)/D20) -> -5.2225791 | I20: =(LN(2*$I$4/D20-1)/-$J$4)*$B$4/100+$B$4 -> 7600000
C21: =C22-500000 -> 8100000 | D21: =2*I$4/(1+EXP(-J$4*((C21-$B$4)/$B$4*100))) -> 3243.453 | E21: =((C22-C20)/C21)/((D22-D20)/D21) -> -4.7063593 | F21: =LN(2*$I$4/D21-1)/-$H$4 -> -56.451613 | G21: =(F21*$B$4/100+$B$4) -> 8100000 | H21: =((G22-G20)/G21)/((D22-D20)/D21) -> -4.7063593 | I21: =(LN(2*$I$4/D21-1)/-$J$4)*$B$4/100+$B$4 -> 8100000
C22: =C23-500000 -> 8600000 | D22: =2*I$4/(1+EXP(-J$4*((C22-$B$4)/$B$4*100))) -> 3200.3379 | E22: =((C23-C21)/C22)/((D23-D21)/D22) -> -4.2596269 | F22: =LN(2*$I$4/D22-1)/-$H$4 -> -53.763441 | G22: =(F22*$B$4/100+$B$4) -> 8600000 | H22: =((G23-G21)/G22)/((D23-D21)/D22) -> -4.2596269 | I22: =(LN(2*$I$4/D22-1)/-$J$4)*$B$4/100+$B$4 -> 8600000
C23: =C24-500000 -> 9100000 | D23: =2*I$4/(1+EXP(-J$4*((C23-$B$4)/$B$4*100))) -> 3156.0904 | E23: =((C24-C22)/C23)/((D24-D22)/D23) -> -3.8704644 | F23: =LN(2*$I$4/D23-1)/-$H$4 -> -51.075269 | G23: =(F23*$B$4/100+$B$4) -> 9100000 | H23: =((G24-G22)/G23)/((D24-D22)/D23) -> -3.8704644 | I23: =(LN(2*$I$4/D23-1)/-$J$4)*$B$4/100+$B$4 -> 9100000
... C41: =C42-500000 -> 18100000 | D41: =2*I$4/(1+EXP(-J$4*((C41-$B$4)/$B$4*100))) -> 2209.2632 | E41: =((C42-C40)/C41)/((D42-D40)/D41) -> -1.0665246 | F41: =LN(2*$I$4/D41-1)/-$H$4 -> -2.688172 | G41: =(F41*$B$4/100+$B$4) -> 18100000 | H41: =((G42-G40)/G41)/((D42-D40)/D41) -> -1.0665246 | I41: =(LN(2*$I$4/D41-1)/-$J$4)*$B$4/100+$B$4 -> 18100000
C42: =B4 -> 18600000 | D42: =2*I$4/(1+EXP(-J$4*((C42-$B$4)/$B$4*100))) -> 2152 | E42: =((C43-C41)/C42)/((D43-D41)/D42) -> -1.0102385 | F42: =LN(2*$I$4/D42-1)/-$H$4 -> 0 | G42: =(F42*$B$4/100+$B$4) -> 18600000 | H42: =((G43-G41)/G42)/((D43-D41)/D42) -> -1.0102385 | I42: =(LN(2*$I$4/D42-1)/-$J$4)*$B$4/100+$B$4 -> 18600000
C43: =C42+500000 -> 19100000 | D43: =2*I$4/(1+EXP(-J$4*((C43-$B$4)/$B$4*100))) -> 2094.7368 | E43: =((C44-C42)/C43)/((D44-D42)/D43) -> -0.95829248 | F43: =LN(2*$I$4/D43-1)/-$H$4 -> 2.688172 | G43: =(F43*$B$4/100+$B$4) -> 19100000 | H43: =((G44-G42)/G43)/((D44-D42)/D43) -> -0.95829248 | I43: =(LN(2*$I$4/D43-1)/-$J$4)*$B$4/100+$B$4 -> 19100000
C44: =C43+500000 -> 19600000 | D44: =2*I$4/(1+EXP(-J$4*((C44-$B$4)/$B$4*100))) -> 2037.5547 | E44: =((C45-C43)/C44)/((D45-D43)/D44) -> -0.91028405 | F44: =LN(2*$I$4/D44-1)/-$H$4 -> 5.3763441 | G44: =(F44*$B$4/100+$B$4) -> 19600000 | H44: =((G45-G43)/G44)/((D45-D43)/D44) -> -0.91028405 | I44: =(LN(2*$I$4/D44-1)/-$J$4)*$B$4/100+$B$4 -> 19600000
C45: =C44+500000 -> 20100000 | D45: =2*I$4/(1+EXP(-J$4*((C45-$B$4)/$B$4*100))) -> 1980.5342 | E45: =((C46-C44)/C45)/((D46-D44)/D45) -> -0.86585429 | F45: =LN(2*$I$4/D45-1)/-$H$4 -> 8.0645161 | G45: =(F45*$B$4/100+$B$4) -> 20100000 | H45: =((G46-G44)/G45)/((D46-D44)/D45) -> -0.86585429 | I45: =(LN(2*$I$4/D45-1)/-$J$4)*$B$4/100+$B$4 -> 20100000
C46: =C45+500000 -> 20600000 | D46: =2*I$4/(1+EXP(-J$4*((C46-$B$4)/$B$4*100))) -> 1923.7549 | E46: =((C47-C45)/C46)/((D47-D45)/D46) -> -0.82468246 | F46: =LN(2*$I$4/D46-1)/-$H$4 -> 10.752688 | G46: =(F46*$B$4/100+$B$4) -> 20600000 | H46: =((G47-G45)/G46)/((D47-D45)/D46) -> -0.82468246 | I46: =(LN(2*$I$4/D46-1)/-$J$4)*$B$4/100+$B$4 -> 20600000
C47: =C46+500000 -> 21100000 | D47: =2*I$4/(1+EXP(-J$4*((C47-$B$4)/$B$4*100))) -> 1867.2952 | E47: =((C48-C46)/C47)/((D48-D46)/D47) -> -0.78648124 | F47: =LN(2*$I$4/D47-1)/-$H$4 -> 13.44086 | G47: =(F47*$B$4/100+$B$4) -> 21100000 | H47: =((G48-G46)/G47)/((D48-D46)/D47) -> -0.78648124 | I47: =(LN(2*$I$4/D47-1)/-$J$4)*$B$4/100+$B$4 -> 21100000
C48: =C47+500000 -> 21600000 | D48: =2*I$4/(1+EXP(-J$4*((C48-$B$4)/$B$4*100))) -> 1811.2317 | E48: =((C49-C47)/C48)/((D49-D47)/D48) -> -0.75099274 | F48: =LN(2*$I$4/D48-1)/-$H$4 -> 16.129032 | G48: =(F48*$B$4/100+$B$4) -> 21600000 | H48: =((G49-G47)/G48)/((D49-D47)/D48) -> -0.75099274 | I48: =(LN(2*$I$4/D48-1)/-$J$4)*$B$4/100+$B$4 -> 21600000
C49: =C48+500000 -> 22100000 | D49: =2*I$4/(1+EXP(-J$4*((C49-$B$4)/$B$4*100))) -> 1755.6386 | E49: =((C50-C48)/C49)/((D50-D48)/D49) -> -0.71798504 | F49: =LN(2*$I$4/D49-1)/-$H$4 -> 18.817204 | G49: =(F49*$B$4/100+$B$4) -> 22100000 | H49: =((G50-G48)/G49)/((D50-D48)/D49) -> -0.71798504 | I49: =(LN(2*$I$4/D49-1)/-$J$4)*$B$4/100+$B$4 -> 22100000
C50: =C49+500000 -> 22600000 | D50: =2*I$4/(1+EXP(-J$4*((C50-$B$4)/$B$4*100))) -> 1700.5878 | E50: =((C51-C49)/C50)/((D51-D49)/D50) -> -0.68724915 | F50: =LN(2*$I$4/D50-1)/-$H$4 -> 21.505376 | G50: =(F50*$B$4/100+$B$4) -> 22600000 | H50: =((G7-G49)/G50)/((D7-D49)/D50) -> -0.78508915 | I50: =(LN(2*$I$4/D50-1)/-$J$4)*$B$4/100+$B$4 -> 22600000
C51: =C50+500000 -> 23100000 | D51: =2*I$4/(1+EXP(-J$4*((C51-$B$4)/$B$4*100))) -> 1646.1481 | E51: =((C52-C50)/C51)/((D52-D50)/D51) -> -0.65859643 | F51: =LN(2*$I$4/D51-1)/-$H$4 -> 24.193548 | G51: =(F51*$B$4/100+$B$4) -> 23100000 | H51: =((G52-G50)/G51)/((D52-D50)/D51) -> -0.65859643 | I51: =(LN(2*$I$4/D51-1)/-$J$4)*$B$4/100+$B$4 -> 23100000
C52: =C51+500000 -> 23600000 | D52: =2*I$4/(1+EXP(-J$4*((C52-$B$4)/$B$4*100))) -> 1592.3852 | E52: =((C53-C51)/C52)/((D53-D51)/D52) -> -0.63185631 | F52: =LN(2*$I$4/D52-1)/-$H$4 -> 26.88172 | G52: =(F52*$B$4/100+$B$4) -> 23600000 | H52: =((G9-G51)/G52)/((D9-D51)/D52) -> -0.69999047 | I52: =(LN(2*$I$4/D52-1)/-$J$4)*$B$4/100+$B$4 -> 23600000
C53: =C52+500000 -> 24100000 | D53: =2*I$4/(1+EXP(-J$4*((C53-$B$4)/$B$4*100))) -> 1539.3612 | E53: =((C54-C52)/C53)/((D54-D52)/D53) -> -0.60687432 | F53: =LN(2*$I$4/D53-1)/-$H$4 -> 29.569892 | G53: =(F53*$B$4/100+$B$4) -> 24100000 | H53: =((G54-G52)/G53)/((D54-D52)/D53) -> -0.60687432 | I53: =(LN(2*$I$4/D53-1)/-$J$4)*$B$4/100+$B$4 -> 24100000
C54: =C53+500000 -> 24600000 | D54: =2*I$4/(1+EXP(-J$4*((C54-$B$4)/$B$4*100))) -> 1487.1346 | E54: =((C55-C53)/C54)/((D55-D53)/D54) -> -0.58351034 | F54: =LN(2*$I$4/D54-1)/-$H$4 -> 32.258065 | G54: =(F54*$B$4/100+$B$4) -> 24600000 | H54: =((G11-G53)/G54)/((D11-D53)/D54) -> -0.61289613 | I54: =(LN(2*$I$4/D54-1)/-$J$4)*$B$4/100+$B$4 -> 24600000
C55: =C54+500000 -> 25100000 | D55: =2*I$4/(1+EXP(-J$4*((C55-$B$4)/$B$4*100))) -> 1435.7596 | E55: =((C56-C54)/C55)/((D56-D54)/D55) -> -0.5616371 | F55: =LN(2*$I$4/D55-1)/-$H$4 -> 34.946237 | G55: =(F55*$B$4/100+$B$4) -> 25100000 | H55: =((G56-G54)/G55)/((D56-D54)/D55) -> -0.5616371 | I55: =(LN(2*$I$4/D55-1)/-$J$4)*$B$4/100+$B$4 -> 25100000
C56: =C55+500000 -> 25600000 | D56: =2*I$4/(1+EXP(-J$4*((C56-$B$4)/$B$4*100))) -> 1385.2866 | E56: =((C57-C55)/C56)/((D57-D55)/D56) -> -0.5411388 | F56: =LN(2*$I$4/D56-1)/-$H$4 -> 37.634409 | G56: =(F56*$B$4/100+$B$4) -> 25600000 | H56: =((G13-G55)/G56)/((D13-D55)/D56) -> -0.53837253 | I56: =(LN(2*$I$4/D56-1)/-$J$4)*$B$4/100+$B$4 -> 25600000
C57: =C56+500000 -> 26100000 | D57: =2*I$4/(1+EXP(-J$4*((C57-$B$4)/$B$4*100))) -> 1335.7617 | E57: =((C58-C56)/C57)/((D58-D56)/D57) -> -0.52190998 | F57: =LN(2*$I$4/D57-1)/-$H$4 -> 40.322581 | G57: =(F57*$B$4/100+$B$4) -> 26100000 | H57: =((G58-G56)/G57)/((D58-D56)/D57) -> -0.52190998 | I57: =(LN(2*$I$4/D57-1)/-$J$4)*$B$4/100+$B$4 -> 26100000
C58: =C57+500000 -> 26600000 | D58: =2*I$4/(1+EXP(-J$4*((C58-$B$4)/$B$4*100))) -> 1287.2264 | E58: =((C59-C57)/C58)/((D59-D57)/D58) -> -0.50385446 | F58: =LN(2*$I$4/D58-1)/-$H$4 -> 43.010753 | G58: =(F58*$B$4/100+$B$4) -> 26600000 | H58: =((G15-G57)/G58)/((D15-D57)/D58) -> -0.4744341 | I58: =(LN(2*$I$4/D58-1)/-$J$4)*$B$4/100+$B$4 -> 26600000
C59: =C58+500000 -> 27100000 | D59: =2*I$4/(1+EXP(-J$4*((C59-$B$4)/$B$4*100))) -> 1239.7181 | E59: =((C60-C58)/C59)/((D60-D58)/D59) -> 0.94532328 | F59: =LN(2*$I$4/D59-1)/-$H$4 -> 45.698925 | G59: =(F59*$B$4/100+$B$4) -> 27100000 | H59: =((G60-G58)/G59)/((D60-D58)/D59) -> 0.94532328 | I59: =(LN(2*$I$4/D59-1)/-$J$4)*$B$4/100+$B$4 -> 27100000

Sheet Elast
A1: =[1]Factors!A1 -> Factor | B1: =[1]Factors!$D$1 -> Ela-sticity
A2: =[1]Factors!A2 -> Pine saw timber | B2: 0
A3: =[1]Factors!A3 -> Pine pulpwood | B3: 0
A4: =[1]Factors!A4 -> Spruce saw timber | B4: 0
A5: =[1]Factors!A5 -> Spruce pulpwood | B5: 0
A6: =[1]Factors!A6 -> Deciduous wood | B6: 0
A7: =[1]Factors!A7 -> Sawdust | B7: 0
A8: =[1]Factors!A8 -> Chips | B8: 0
A9: =[1]Factors!A9 -> Residues above gr. | B9: 0
A10: =[1]Factors!A10 -> Stump and roots | B10: 0
A11: =[1]Factors!A14 -> Sawn wood | B11: =B26 -> -0.12254296 | C11: använd elastic. för coniferous sawnwood (non-coniferous mycket liten i jämförelse)
A12: =[1]Factors!A15 -> Heat | B12: 1
A13: =[1]Factors!A16 -> Electricity | B13: 1
A14: =[1]Factors!A17 -> Biofuel | B14: 1
A15: =[1]Factors!A18 -> Pulp chem. process | B15: =-0.5 -> -0.5 | C15: The Nordic Forest Sector Model (NFSM): Data and Model Structure
A16: =[1]Factors!A19 -> Pulp mech. process | B16: =-0.5 -> -0.5 | C16: The Nordic Forest Sector Model (NFSM): Data and Model Structure
A17: =[1]Factors!A20 -> Dissolving pulp | B17: =-1.93 -> -1.93
A18: =[1]Factors!A21 -> Packaging | B18: =B33 -> -0.31123036 | C18: använd elastic. för packaging paper (Hh & sanitary väldigt liten volymdel av Op &Pb)
A19: =[1]Factors!A22 -> Other paper chem. | B19: =B32 -> -0.49445163 | C19: använd elastic. för Printing & writing paper
A20: =[1]Factors!A23 -> Other paper mech. | B20: =B32 -> -0.49445163 | C20: använd elastic. för Printing & writing paper
A21: =[1]Factors!A24 -> Newsprint | B21: =B31 -> -0.53473891 | C21: Newsprint elasticitet
C25: Källa priselasticitet | I25: Källa export | M25: Produktkod (Item code/Commodity code) | N25: Källa produktion | V25: Produktkod (Item code)
A26: Coniferous sawnwood | B26: -0.12254296 | C26: GFTM demand elasticities: The Global Forest Trade Model - GFTM. DOI: 10.2788/666206 | I26: FAOSTAT Forestry Trade Flows: http://www.fao.org/faostat/en/#data/FT | M26: 1632 | N26: FAOSTAT Forestry Production and Trade: http://www.fao.org/faostat/en/#data/FO | V26: 1632
A27: Non-conigerous sawnwood | B27: -0.16607278 | C27: GFTM demand elasticities: The Global Forest Trade Model - GFTM. DOI: 10.2788/666207 | I27: FAOSTAT Forestry Trade Flows: http://www.fao.org/faostat/en/#data/FT | M27: 1633 | N27: FAOSTAT Forestry Production and Trade: http://www.fao.org/faostat/en/#data/FO | V27: 1633
A28: Plywood och fane'r | B28: -0.37292878 | C28: GFTM demand elasticities: The Global Forest Trade Model - GFTM. DOI: 10.2788/666208 | I28: FAOSTAT Forestry Trade Flows: http://www.fao.org/faostat/en/#data/FT | M28: 1640 | N28: FAOSTAT Forestry Production and Trade: http://www.fao.org/faostat/en/#data/FO | V28: 1640
A29: Particle board | B29: -0.32155056 | C29: GFTM demand elasticities: The Global Forest Trade Model - GFTM. DOI: 10.2788/666209 | I29: UN Comtrade Database: https://comtrade.un.org/data | M29: 4410 | N29: FAOSTAT Forestry Production and Trade: http://www.fao.org/faostat/en/#data/FO | V29: 1697
A30: Fibreboard | B30: -0.46439097 | C30: GFTM demand elasticities: The Global Forest Trade Model - GFTM. DOI: 10.2788/666210 | I30: NO Swedish Fibreboard production, use GFTM value for Sweden | M30: - | V30: -
A31: Newsprint | B31: -0.53473891 | C31: GFTM demand elasticities: The Global Forest Trade Model - GFTM. DOI: 10.2788/666211 | I31: FAOSTAT Forestry Trade Flows: http://www.fao.org/faostat/en/#data/FT | M31: 1671 | N31: FAOSTAT Forestry Production and Trade: http://www.fao.org/faostat/en/#data/FO | V31: 1671
A32: Printing & writing paper | B32: -0.49445163 | C32: GFTM demand elasticities: The Global Forest Trade Model - GFTM. DOI: 10.2788/666212 | I32: UN Comtrade Database: https://comtrade.un.org/data | M32: 4802 | N32: FAOSTAT Forestry Production and Trade: http://www.fao.org/faostat/en/#data/FO | V32: 1674
A33: Packaging paper | B33: -0.31123036 | C33: GFTM demand elasticities: The Global Forest Trade Model - GFTM. DOI: 10.2788/666213 | I33: UN Comtrade Database: https://comtrade.un.org/data | M33: 4804 | N33: FAOSTAT Forestry Production and Trade: http://www.fao.org/faostat/en/#data/FO | V33: 1618
A34: Houselhold & sanitary paper | B34: -0.069750013 | C34: GFTM demand elasticities: The Global Forest Trade Model - GFTM. DOI: 10.2788/666214 | I34: UN Comtrade Database: https://comtrade.un.org/data | M34: 481810 | N34: FAOSTAT Forestry Production and Trade: http://www.fao.org/faostat/en/#data/FO | V34: 1676
A37: Priselasticiteten för en given produkt är ett vägt tre-årsmedelvärde (2015-2017),
A38: baserat på elasticiteten för de sex största exportmarknaderna och den svenska elasticteten,
A39: givet exportmarknadernas andel (av deras gemensamma import från Sverige) samt exportens andel av svensk produktion.
A41: Facility type | B41: Output (factor name in brackets)
A43: Sawmal | B43: Sawn wood (väsentligen en exportprodukt!)
A44: Heatpl | B44: (Heat__) Energy
A45: (CHPpl_) | B45: -
A46: PuChem | B46: (PuChem) Chemical wood pulp, sulphate / sulphite, bleached
A47: PuMech | B47: (PuMech) Mechanical and semi-chemical wood pulp
...

Sheet BCCS
G1: kt CO2/y | H1: kton/y | I1: ton CO2/ton output
A2: PP-01 | B2: Södra Cell Mönsterås | C2: Pulp | D2: Recovery boiler, Lime kiln | E2: 1811 | F2: 23 | G2: 1834 | H2: 700 | I2: =G2/H2 -> 2.62
A3: PP-09 | B3: Södra Cell Mörrum | C3: Pulp | D3: Recovery boiler, Lime kiln | E3: 952 | F3: 17 | G3: 969 | H3: 600 | I3: =G3/H3 -> 1.615
A4: PP-02 | B4: Stora Enso Skutskär | C4: Pulp | D4: Recovery boiler, Lime kiln | E4: 1826 | F4: 1 | G4: 1826 | H4: 500 | I4: =G4/H4 -> 3.652
A5: PP-11 | B5: Stora Enso Skoghall | C5: Pulp and Paper | D5: Recovery boiler, Lime kiln | E5: 889 | F5: 53 | G5: 943 | H5: 675 | I5: =G5/H5 -> 1.397037
A6: PP-14 | B6: Stora Enso Nymölla | C6: Pulp and Paper | D6: Recovery boiler | E6: 746 | F6: 30 | G6: 775 | H6: 400 | I6: =G6/H6 -> 1.9375
A7: PP-07 | B7: Smurfit Kappa Kraftliner Piteå | C7: Pulp and Paper | D7: Recovery boiler, Lime kiln | E7: 1120 | F7: 13 | G7: 1133 | H7: 700 | I7: =G7/H7 -> 1.6185714
A8: PP-15 | B8: SCA Munksund | C8: Pulp and Paper | D8: Recovery boiler, Lime kiln | E8: 689 | F8: 17 | G8: 706 | H8: 300 | I8: =G8/H8 -> 2.3533333
A9: PP-18 | B9: Rottneros, Vallviks Bruk | C9: Pulp | D9: Recovery boiler, Lime kiln | E9: 604 | F9: 6 | G9: 610 | H9: 150 | I9: =G9/H9 -> 4.0666667
A10: PP-19 | B10: Nordic Paper, Bäckhammar | C10: Pulp and Paper | D10: Recovery boiler, Lime kiln | E10: 539 | F10: 7 | G10: 546 | H10: 230 | I10: =G10/H10 -> 2.373913
A11: PP-17 | B11: Mondi Dynäs | C11: Pulp and Paper | D11: Recovery boiler, Lime kiln | E11: 633 | F11: 15 | G11: 648 | H11: 225 | I11: =G11/H11 -> 2.88
A12: PP-03 | B12: Metsä Board Husum | C12: Pulp and Paper | D12: Recovery boiler, Lime kiln | E12: 1483 | F12: 60 | G12: 1543 | H12: 650 | I12: =G12/H12 -> 2.3738462
A13: PP-12 | B13: Holmen Iggesund | C13: Pulp and Paper | D13: Recovery boiler, Lime kiln | E13: 884 | F13: 27 | G13: 911 | H13: 540 | I13: =G13/H13 -> 1.687037
... A21: PP-06 | B21: SCA Östrand | C21: Pulp | D21: Recovery boiler, Lime kiln | E21: 1135 | F21: 32 | G21: 1166 | H21: 900 | I21: =G21/H21 -> 1.2955556
G22: =SUM(G2:G21) -> 20202 | H22: =SUM(H2:H21) -> 9830 | I22: {=MMULT(TRANSPOSE(H2:H21),I2:I21)/H22} -> 2.0551373 | J22: Average ton CO2/ton output
G23: =I23 -> 0.83333333 | I23: =3/3600*1000 -> 0.83333333 | J23: MWh per ton CO2
G24: =G22*1000*G23 -> 16835000 | I24: =I22*I23 -> 1.7126144 | J24: MWh electricity per ton output
H25: =H22*1000*I24 -> 16835000 | J25: Total MWh
I26: 0.907 | J26: Onarheim MWh electricity per ton output - pulp mill
I27: 0.44 | J27: Onarheim MWh electricity per ton output - integrated

Sheet Biofuel
A1: Biofuel | F1: Profu scenarios
