Workbook

Sheet HeatingPlants
K1: 1 | N1: 100 | O1: 2 | R1: 0.7 | S1: 3 | W1: Original capacity
A2: Location | B2: Facility | C2: County | D2: NUTS2 | E2: =[1]SummaryTable!B1 -> GpsNorth | F2: =[1]SummaryTable!C1 -> GPSEast | G2: Capacity | H2: =[1]SummaryTable!E1 -> ShareHeat | I2: =[1]SummaryTable!F1 -> ShareEl | J2: Type | K2: Linje | L2: Location | M2: Type | N2: Capacity | O2: Linje | P2: Location | Q2: Type | R2: Capacity | S2: Linje | T2: Location | U2: Type | V2: Capacity | W2: =[1]SummaryTable!D1 -> TotalDeliveries
A3: H181 | B3: =A3 -> H181 | C3: 1 | D3: 12 | E3: =VLOOKUP(A3,[1]SummaryTable!$A$2:$F$359,2,FALSE) -> 6583451.2 | F3: =VLOOKUP(A3,[1]SummaryTable!$A$2:$F$359,3,FALSE) -> 676414.23 | G3: =1.2*W3 -> 3685.0797 | H3: =VLOOKUP(A3,[1]SummaryTable!$A$2:$F$359,5,FALSE) -> 0.53667544 | I3: =VLOOKUP(A3,[1]SummaryTable!$A$2:$F$359,6,FALSE) -> 0.46332456 | J3: =IF(I3>0.1,[2]Processes!$A$6,[2]Processes!$A$5) -> Heatpl | K3: =IF(G3>$N$1,$A3&"L"&K$1,"-") -> H181L1 | L3: =IF(K3="-","-",$A3) -> H181 | M3: =IF(L3="-","-","Heatpl") -> Heatpl | N3: =IF(M3="-",0,G3) -> 3685.0797 | O3: =IF(G3*I3>$N$1,$A3&"L"&O$1,"-") -> H181L2 | P3: =IF(O3="-","-",A3) -> H181 | Q3: =IF(P3="-","-","CHPpl_") -> CHPpl_ | R3: =IF(Q3="-",0,G3*$R$1) -> 2579.5558 | S3: =IF(G3>$N$1,$A3&"L"&S$1,"-") -> H181L3 | T3: =IF(S3="-","-",$A3) -> H181 | U3: =IF(T3="-","-","TerHea") -> TerHea | V3: =IF(U3="-",0,9999) -> 9999 | W3: =VLOOKUP(A3,[1]SummaryTable!$A$2:$F$359,4,FALSE) -> 3070.8997
A4: H190 | B4: =A4 -> H190 | C4: 18 | D4: 12 | E4: =VLOOKUP(A4,[1]SummaryTable!$A$2:$F$359,2,FALSE) -> 6568953.1 | F4: =VLOOKUP(A4,[1]SummaryTable!$A$2:$F$359,3,FALSE) -> 512314.15 | G4: =1.2*W4 -> 1073.0699 | H4: =VLOOKUP(A4,[1]SummaryTable!$A$2:$F$359,5,FALSE) -> 0.51609342 | I4: =VLOOKUP(A4,[1]SummaryTable!$A$2:$F$359,6,FALSE) -> 0.48390658 | J4: =IF(I4>0.1,[2]Processes!$A$6,[2]Processes!$A$5) -> Heatpl | K4: =IF(G4>$N$1,$A4&"L"&K$1,"-") -> H190L1 | L4: =IF(K4="-","-",$A4) -> H190 | M4: =IF(L4="-","-","Heatpl") -> Heatpl | N4: =IF(M4="-",0,G4) -> 1073.0699 | O4: =IF(G4*I4>$N$1,$A4&"L"&O$1,"-") -> H190L2 | P4: =IF(O4="-","-",A4) -> H190 | Q4: =IF(P4="-","-","CHPpl_") -> CHPpl_ | R4: =IF(Q4="-",0,G4*I4) -> 519.26558 | S4: =IF(G4>$N$1,$A4&"L"&S$1,"-") -> H190L3 | T4: =IF(S4="-","-",$A4) -> H190 | U4: =IF(T4="-","-","TerHea") -> TerHea | V4: =IF(U4="-",0,9999) -> 9999 | W4: =VLOOKUP(A4,[1]SummaryTable!$A$2:$F$359,4,FALSE) -> 894.2249
A5: H176 | B5: =A5 -> H176 | C5: 4 | D5: 12 | E5: =VLOOKUP(A5,[1]SummaryTable!$A$2:$F$359,2,FALSE) -> 6586695.1 | F5: =VLOOKUP(A5,[1]SummaryTable!$A$2:$F$359,3,FALSE) -> 583369.67 | G5: =1.2*W5 -> 1008.2172 | H5: =VLOOKUP(A5,[1]SummaryTable!$A$2:$F$359,5,FALSE) -> 0.65371669 | I5: =VLOOKUP(A5,[1]SummaryTable!$A$2:$F$359,6,FALSE) -> 0.34628331 | J5: =IF(I5>0.1,[2]Processes!$A$6,[2]Processes!$A$5) -> Heatpl | K5: =IF(G5>$N$1,$A5&"L"&K$1,"-") -> H176L1 | L5: =IF(K5="-","-",$A5) -> H176 | M5: =IF(L5="-","-","Heatpl") -> Heatpl | N5: =IF(M5="-",0,G5) -> 1008.2172 | O5: =IF(G5*I5>$N$1,$A5&"L"&O$1,"-") -> H176L2 | P5: =IF(O5="-","-",A5) -> H176 | Q5: =IF(P5="-","-","CHPpl_") -> CHPpl_ | R5: =IF(Q5="-",0,G5*I5) -> 349.12878 | S5: =IF(G5>$N$1,$A5&"L"&S$1,"-") -> H176L3 | T5: =IF(S5="-","-",$A5) -> H176 | U5: =IF(T5="-","-","TerHea") -> TerHea | V5: =IF(U5="-",0,9999) -> 9999 | W5: =VLOOKUP(A5,[1]SummaryTable!$A$2:$F$359,4,FALSE) -> 840.181
A6: H320 | B6: =A6 -> H320 | C6: 7 | D6: 21 | E6: =VLOOKUP(A6,[1]SummaryTable!$A$2:$F$359,2,FALSE) -> 6302421.5 | F6: =VLOOKUP(A6,[1]SummaryTable!$A$2:$F$359,3,FALSE) -> 488455.87 | G6: =1.2*W6 -> 920.64 | H6: =VLOOKUP(A6,[1]SummaryTable!$A$2:$F$359,5,FALSE) -> 0.49060846 | I6: =VLOOKUP(A6,[1]SummaryTable!$A$2:$F$359,6,FALSE) -> 0.50939154 | J6: =IF(I6>0.1,[2]Processes!$A$6,[2]Processes!$A$5) -> Heatpl | K6: =IF(G6>$N$1,$A6&"L"&K$1,"-") -> H320L1 | L6: =IF(K6="-","-",$A6) -> H320 | M6: =IF(L6="-","-","Heatpl") -> Heatpl | N6: =IF(M6="-",0,G6) -> 920.64 | O6: =IF(G6*I6>$N$1,$A6&"L"&O$1,"-") -> H320L2 | P6: =IF(O6="-","-",A6) -> H320 | Q6: =IF(P6="-","-","CHPpl_") -> CHPpl_ | R6: =IF(Q6="-",0,G6*I6) -> 468.96623 | S6: =IF(G6>$N$1,$A6&"L"&S$1,"-") -> H320L3 | T6: =IF(S6="-","-",$A6) -> H320 | U6: =IF(T6="-","-","TerHea") -> TerHea | V6: =IF(U6="-",0,9999) -> 9999 | W6: =VLOOKUP(A6,[1]SummaryTable!$A$2:$F$359,4,FALSE) -> 767.2
A7: H86 | B7: =A7 -> H86 | C7: 23 | D7: 12 | E7: =VLOOKUP(A7,[1]SummaryTable!$A$2:$F$359,2,FALSE) -> 7002099.5 | F7: =VLOOKUP(A7,[1]SummaryTable!$A$2:$F$359,3,FALSE) -> 481788.13 | G7: =1.2*W7 -> 683.03964 | H7: =VLOOKUP(A7,[1]SummaryTable!$A$2:$F$359,5,FALSE) -> 0.52621228 | I7: =VLOOKUP(A7,[1]SummaryTable!$A$2:$F$359,6,FALSE) -> 0.47378772 | J7: =IF(I7>0.1,[2]Processes!$A$6,[2]Processes!$A$5) -> Heatpl | K7: =IF(G7>$N$1,$A7&"L"&K$1,"-") -> H86L1 | L7: =IF(K7="-","-",$A7) -> H86 | M7: =IF(L7="-","-","Heatpl") -> Heatpl | N7: =IF(M7="-",0,G7) -> 683.03964 | O7: =IF(G7*I7>$N$1,$A7&"L"&O$1,"-") -> H86L2 | P7: =IF(O7="-","-",A7) -> H86 | Q7: =IF(P7="-","-","CHPpl_") -> CHPpl_ | R7: =IF(Q7="-",0,G7*I7) -> 323.61579 | S7: =IF(G7>$N$1,$A7&"L"&S$1,"-") -> H86L3 | T7: =IF(S7="-","-",$A7) -> H86 | U7: =IF(T7="-","-","TerHea") -> TerHea | V7: =IF(U7="-",0,9999) -> 9999 | W7: =VLOOKUP(A7,[1]SummaryTable!$A$2:$F$359,4,FALSE) -> 569.1997
A8: H182 | B8: =A8 -> H182 | C8: 17 | D8: 31 | E8: =VLOOKUP(A8,[1]SummaryTable!$A$2:$F$359,2,FALSE) -> 6579972 | F8: =VLOOKUP(A8,[1]SummaryTable!$A$2:$F$359,3,FALSE) -> 414797.68 | G8: =1.2*W8 -> 671.9424 | H8: =VLOOKUP(A8,[1]SummaryTable!$A$2:$F$359,5,FALSE) -> 0.6084975 | I8: =VLOOKUP(A8,[1]SummaryTable!$A$2:$F$359,6,FALSE) -> 0.3915025 | J8: =IF(I8>0.1,[2]Processes!$A$6,[2]Processes!$A$5) -> Heatpl | K8: =IF(G8>$N$1,$A8&"L"&K$1,"-") -> H182L1 | L8: =IF(K8="-","-",$A8) -> H182 | M8: =IF(L8="-","-","Heatpl") -> Heatpl | N8: =IF(M8="-",0,G8) -> 671.9424 | O8: =IF(G8*I8>$N$1,$A8&"L"&O$1,"-") -> H182L2 | P8: =IF(O8="-","-",A8) -> H182 | Q8: =IF(P8="-","-","CHPpl_") -> CHPpl_ | R8: =IF(Q8="-",0,G8*I8) -> 263.06713 | S8: =IF(G8>$N$1,$A8&"L"&S$1,"-") -> H182L3 | T8: =IF(S8="-","-",$A8) -> H182 | U8: =IF(T8="-","-","TerHea") -> TerHea | V8: =IF(U8="-",0,9999) -> 9999 | W8: =VLOOKUP(A8,[1]SummaryTable!$A$2:$F$359,4,FALSE) -> 559.952
A9: H268 | B9: =A9 -> H268 | C9: 6 | D9: 21 | E9: =VLOOKUP(A9,[1]SummaryTable!$A$2:$F$359,2,FALSE) -> 6402243.1 | F9: =VLOOKUP(A9,[1]SummaryTable!$A$2:$F$359,3,FALSE) -> 450109.38 | G9: =1.2*W9 -> 664.716 | H9: =VLOOKUP(A9,[1]SummaryTable!$A$2:$F$359,5,FALSE) -> 0.58766182 | I9: =VLOOKUP(A9,[1]SummaryTable!$A$2:$F$359,6,FALSE) -> 0.41233818 | J9: =IF(I9>0.1,[2]Processes!$A$6,[2]Processes!$A$5) -> Heatpl | K9: =IF(G9>$N$1,$A9&"L"&K$1,"-") -> H268L1 | L9: =IF(K9="-","-",$A9) -> H268 | M9: =IF(L9="-","-","Heatpl") -> Heatpl | N9: =IF(M9="-",0,G9) -> 664.716 | O9: =IF(G9*I9>$N$1,$A9&"L"&O$1,"-") -> H268L2 | P9: =IF(O9="-","-",A9) -> H268 | Q9: =IF(P9="-","-","CHPpl_") -> CHPpl_ | R9: =IF(Q9="-",0,G9*I9) -> 274.08779 | S9: =IF(G9>$N$1,$A9&"L"&S$1,"-") -> H268L3 | T9: =IF(S9="-","-",$A9) -> H268 | U9: =IF(T9="-","-","TerHea") -> TerHea | V9: =IF(U9="-",0,9999) -> 9999 | W9: =VLOOKUP(A9,[1]SummaryTable!$A$2:$F$359,4,FALSE) -> 553.93
A10: H326 | B10: =A10 -> H326 | C10: 8 | D10: 21 | E10: =VLOOKUP(A10,[1]SummaryTable!$A$2:$F$359,2,FALSE) -> 6279434.1 | F10: =VLOOKUP(A10,[1]SummaryTable!$A$2:$F$359,3,FALSE) -> 583418.89 | G10: =1.2*W10 -> 637.08 | H10: =VLOOKUP(A10,[1]SummaryTable!$A$2:$F$359,5,FALSE) -> 0.52461777 | I10: =VLOOKUP(A10,[1]SummaryTable!$A$2:$F$359,6,FALSE) -> 0.47538223 | J10: =IF(I10>0.1,[2]Processes!$A$6,[2]Processes!$A$5) -> Heatpl | K10: =IF(G10>$N$1,$A10&"L"&K$1,"-") -> H326L1 | L10: =IF(K10="-","-",$A10) -> H326 | M10: =IF(L10="-","-","Heatpl") -> Heatpl | N10: =IF(M10="-",0,G10) -> 637.08 | O10: =IF(G10*I10>$N$1,$A10&"L"&O$1,"-") -> H326L2 | P10: =IF(O10="-","-",A10) -> H326 | Q10: =IF(P10="-","-","CHPpl_") -> CHPpl_ | R10: =IF(Q10="-",0,G10*I10) -> 302.85651 | S10: =IF(G10>$N$1,$A10&"L"&S$1,"-") -> H326L3 | T10: =IF(S10="-","-",$A10) -> H326 | U10: =IF(T10="-","-","TerHea") -> TerHea | V10: =IF(U10="-",0,9999) -> 9999 | W10: =VLOOKUP(A10,[1]SummaryTable!$A$2:$F$359,4,FALSE) -> 530.9
A11: H274 | B11: =A11 -> H274 | C11: 14 | D11: 23 | E11: =VLOOKUP(A11,[1]SummaryTable!$A$2:$F$359,2,FALSE) -> 6396012.8 | F11: =VLOOKUP(A11,[1]SummaryTable!$A$2:$F$359,3,FALSE) -> 376954.59 | G11: =1.2*W11 -> 621.8634 | H11: =VLOOKUP(A11,[1]SummaryTable!$A$2:$F$359,5,FALSE) -> 0.74670371 | I11: =VLOOKUP(A11,[1]SummaryTable!$A$2:$F$359,6,FALSE) -> 0.25329629 | J11: =IF(I11>0.1,[2]Processes!$A$6,[2]Processes!$A$5) -> Heatpl | K11: =IF(G11>$N$1,$A11&"L"&K$1,"-") -> H274L1 | L11: =IF(K11="-","-",$A11) -> H274 | M11: =IF(L11="-","-","Heatpl") -> Heatpl | N11: =IF(M11="-",0,G11) -> 621.8634 | O11: =IF(G11*I11>$N$1,$A11&"L"&O$1,"-") -> H274L2 | P11: =IF(O11="-","-",A11) -> H274 | Q11: =IF(P11="-","-","CHPpl_") -> CHPpl_ | R11: =IF(Q11="-",0,G11*I11) -> 157.51569 | S11: =IF(G11>$N$1,$A11&"L"&S$1,"-") -> H274L3 | T11: =IF(S11="-","-",$A11) -> H274 | U11: =IF(T11="-","-","TerHea") -> TerHea | V11: =IF(U11="-",0,9999) -> 9999 | W11: =VLOOKUP(A11,[1]SummaryTable!$A$2:$F$359,4,FALSE) -> 518.2195
A12: H72 | B12: =A12 -> H72 | C12: 24 | D12: 33 | E12: =VLOOKUP(A12,[1]SummaryTable!$A$2:$F$359,2,FALSE) -> 7094648.9 | F12: =VLOOKUP(A12,[1]SummaryTable!$A$2:$F$359,3,FALSE) -> 765953.48 | G12: =1.2*W12 -> 588.948 | H12: =VLOOKUP(A12,[1]SummaryTable!$A$2:$F$359,5,FALSE) -> 0.58862123 | I12: =VLOOKUP(A12,[1]SummaryTable!$A$2:$F$359,6,FALSE) -> 0.41137877 | J12: =IF(I12>0.1,[2]Processes!$A$6,[2]Processes!$A$5) -> Heatpl | K12: =IF(G12>$N$1,$A12&"L"&K$1,"-") -> H72L1 | L12: =IF(K12="-","-",$A12) -> H72 | M12: =IF(L12="-","-","Heatpl") -> Heatpl | N12: =IF(M12="-",0,G12) -> 588.948 | O12: =IF(G12*I12>$N$1,$A12&"L"&O$1,"-") -> H72L2 | P12: =IF(O12="-","-",A12) -> H72 | Q12: =IF(P12="-","-","CHPpl_") -> CHPpl_ | R12: =IF(Q12="-",0,G12*I12) -> 242.28071 | S12: =IF(G12>$N$1,$A12&"L"&S$1,"-") -> H72L3 | T12: =IF(S12="-","-",$A12) -> H72 | U12: =IF(T12="-","-","TerHea") -> TerHea | V12: =IF(U12="-",0,9999) -> 9999 | W12: =VLOOKUP(A12,[1]SummaryTable!$A$2:$F$359,4,FALSE) -> 490.79
A13: H348 | B13: =A13 -> H348 | C13: 12 | D13: 22 | E13: =VLOOKUP(A13,[1]SummaryTable!$A$2:$F$359,2,FALSE) -> 6209659.4 | F13: =VLOOKUP(A13,[1]SummaryTable!$A$2:$F$359,3,FALSE) -> 356474.53 | G13: =1.2*W13 -> 564.48 | H13: =VLOOKUP(A13,[1]SummaryTable!$A$2:$F$359,5,FALSE) -> 0.48830679 | I13: =VLOOKUP(A13,[1]SummaryTable!$A$2:$F$359,6,FALSE) -> 0.51169321 | J13: =IF(I13>0.1,[2]Processes!$A$6,[2]Processes!$A$5) -> Heatpl | K13: =IF(G13>$N$1,$A13&"L"&K$1,"-") -> H348L1 | L13: =IF(K13="-","-",$A13) -> H348 | M13: =IF(L13="-","-","Heatpl") -> Heatpl | N13: =IF(M13="-",0,G13) -> 564.48 | O13: =IF(G13*I13>$N$1,$A13&"L"&O$1,"-") -> H348L2 | P13: =IF(O13="-","-",A13) -> H348 | Q13: =IF(P13="-","-","CHPpl_") -> CHPpl_ | R13: =IF(Q13="-",0,G13*I13) -> 288.84059 | S13: =IF(G13>$N$1,$A13&"L"&S$1,"-") -> H348L3 | T13: =IF(S13="-","-",$A13) -> H348 | U13: =IF(T13="-","-","TerHea") -> TerHea | V13: =IF(U13="-",0,9999) -> 9999 | W13: =VLOOKUP(A13,[1]SummaryTable!$A$2:$F$359,4,FALSE) -> 470.4
A14: H350 | B14: =A14 -> H350 | C14: 12 | D14: 22 | E14: =VLOOKUP(A14,[1]SummaryTable!$A$2:$F$359,2,FALSE) -> 6207231.8 | F14: =VLOOKUP(A14,[1]SummaryTable!$A$2:$F$359,3,FALSE) -> 447164.47 | G14: =1.2*W14 -> 530.6604 | H14: =VLOOKUP(A14,[1]SummaryTable!$A$2:$F$359,5,FALSE) -> 0.61084259 | I14: =VLOOKUP(A14,[1]SummaryTable!$A$2:$F$359,6,FALSE) -> 0.38915741 | J14: =IF(I14>0.1,[2]Processes!$A$6,[2]Processes!$A$5) -> Heatpl | K14: =IF(G14>$N$1,$A14&"L"&K$1,"-") -> H350L1 | L14: =IF(K14="-","-",$A14) -> H350 | M14: =IF(L14="-","-","Heatpl") -> Heatpl | N14: =IF(M14="-",0,G14) -> 530.6604 | O14: =IF(G14*I14>$N$1,$A14&"L"&O$1,"-") -> H350L2 | P14: =IF(O14="-","-",A14) -> H350 | Q14: =IF(P14="-","-","CHPpl_") -> CHPpl_ | R14: =IF(Q14="-",0,G14*I14) -> 206.51043 | S14: =IF(G14>$N$1,$A14&"L"&S$1,"-") -> H350L3 | T14: =IF(S14="-","-",$A14) -> H350 | U14: =IF(T14="-","-","TerHea") -> TerHea | V14: =IF(U14="-",0,9999) -> 9999 | W14: =VLOOKUP(A14,[1]SummaryTable!$A$2:$F$359,4,FALSE) -> 442.217
A15: H158 | B15: =A15 -> H158 | C15: 19 | D15: 12 | E15: =VLOOKUP(A15,[1]SummaryTable!$A$2:$F$359,2,FALSE) -> 6608483.1 | F15: =VLOOKUP(A15,[1]SummaryTable!$A$2:$F$359,3,FALSE) -> 587306.32 | G15: =1.2*W15 -> 524.19596 | H15: =VLOOKUP(A15,[1]SummaryTable!$A$2:$F$359,5,FALSE) -> 0.93967469 | I15: =VLOOKUP(A15,[1]SummaryTable!$A$2:$F$359,6,FALSE) -> 0.060325314 | J15: =IF(I15>0.1,[2]Processes!$A$6,[2]Processes!$A$5) -> Sawmal | K15: =IF(G15>$N$1,$A15&"L"&K$1,"-") -> H158L1 | L15: =IF(K15="-","-",$A15) -> H158 | M15: =IF(L15="-","-","Heatpl") -> Heatpl | N15: =IF(M15="-",0,G15) -> 524.19596 | O15: =IF(G15*I15>$N$1,$A15&"L"&O$1,"-") -> - | P15: =IF(O15="-","-",A15) -> - | Q15: =IF(P15="-","-","CHPpl_") -> - | R15: =IF(Q15="-",0,G15*I15) -> 0 | S15: =IF(G15>$N$1,$A15&"L"&S$1,"-") -> H158L3 | T15: =IF(S15="-","-",$A15) -> H158 | U15: =IF(T15="-","-","TerHea") -> TerHea | V15: =IF(U15="-",0,9999) -> 9999 | W15: =VLOOKUP(A15,[1]SummaryTable!$A$2:$F$359,4,FALSE) -> 436.82996
... A89: H279 | B89: =A89 -> H279 | C89: 14 | D89: 23 | E89: =VLOOKUP(A89,[1]SummaryTable!$A$2:$F$359,2,FALSE) -> 6390245 | F89: =VLOOKUP(A89,[1]SummaryTable!$A$2:$F$359,3,FALSE) -> 322019.98 | G89: =1.2*W89 -> 78.6012 | H89: =VLOOKUP(A89,[1]SummaryTable!$A$2:$F$359,5,FALSE) -> 0.46132637 | I89: =VLOOKUP(A89,[1]SummaryTable!$A$2:$F$359,6,FALSE) -> 0.53867363 | J89: =IF(I89>0.1,[2]Processes!$A$6,[2]Processes!$A$5) -> Heatpl | K89: =IF(G89>$N$1,$A89&"L"&K$1,"-") -> - | L89: =IF(K89="-","-",$A89) -> - | M89: =IF(L89="-","-","Heatpl") -> - | N89: =IF(M89="-",0,G89) -> 0 | O89: =IF(G89*I89>$N$1,$A89&"L"&O$1,"-") -> - | P89: =IF(O89="-","-",A89) -> - | Q89: =IF(P89="-","-","CHPpl_") -> - | R89: =IF(Q89="-",0,G89*I89) -> 0 | S89: =IF(G89>$N$1,$A89&"L"&S$1,"-") -> - | T89: =IF(S89="-","-",$A89) -> - | U89: =IF(T89="-","-","TerHea") -> - | V89: =IF(U89="-",0,9999) -> 0 | W89: =VLOOKUP(A89,[1]SummaryTable!$A$2:$F$359,4,FALSE) -> 65.501
A90: H328 | B90: =A90 -> H328 | C90: 7 | D90: 21 | E90: =VLOOKUP(A90,[1]SummaryTable!$A$2:$F$359,2,FALSE) -> 6265690.2 | F90: =VLOOKUP(A90,[1]SummaryTable!$A$2:$F$359,3,FALSE) -> 446717.06 | G90: 500 | H90: =VLOOKUP(A90,[1]SummaryTable!$A$2:$F$359,5,FALSE) -> 1 | I90: =VLOOKUP(A90,[1]SummaryTable!$A$2:$F$359,6,FALSE) -> 0 | J90: =IF(I90>0.1,[2]Processes!$A$6,[2]Processes!$A$5) -> Sawmal | K90: =IF(G90>$N$1,$A90&"L"&K$1,"-") -> H328L1 | L90: =IF(K90="-","-",$A90) -> H328 | M90: ParBoa | N90: =IF(M90="-",0,G90) -> 500 | O90: =IF(G90>$N$1,$A90&"L"&O$1,"-") -> H328L2 | P90: =IF(O90="-","-",$A90) -> H328 | Q90: =IF(P90="-","-","TerPal") -> TerPal | R90: =IF(Q90="-",0,9999) -> 9999 | S90: =IF(G90>$N$1,$A90&"L"&S$1,"-") -> H328L3 | T90: =IF(S90="-","-",$A90) -> H328 | U90: =IF(T90="-","-","TerHea") -> TerHea | V90: 0 | W90: =VLOOKUP(A90,[1]SummaryTable!$A$2:$F$359,4,FALSE) -> 65.45
A91: H129 | B91: =A91 -> H129 | C91: 3 | D91: 12 | E91: =VLOOKUP(A91,[1]SummaryTable!$A$2:$F$359,2,FALSE) -> 6691845.9 | F91: =VLOOKUP(A91,[1]SummaryTable!$A$2:$F$359,3,FALSE) -> 638746.25 | G91: =1.2*W91 -> 78.36 | H91: =VLOOKUP(A91,[1]SummaryTable!$A$2:$F$359,5,FALSE) -> 1 | I91: =VLOOKUP(A91,[1]SummaryTable!$A$2:$F$359,6,FALSE) -> 0 | J91: =IF(I91>0.1,[2]Processes!$A$6,[2]Processes!$A$5) -> Sawmal | K91: =IF(G91>$N$1,$A91&"L"&K$1,"-") -> - | L91: =IF(K91="-","-",$A91) -> - | M91: =IF(L91="-","-","Heatpl") -> - | N91: =IF(M91="-",0,G91) -> 0 | O91: =IF(G91*I91>$N$1,$A91&"L"&O$1,"-") -> - | P91: =IF(O91="-","-",A91) -> - | Q91: =IF(P91="-","-","CHPpl_") -> - | R91: =IF(Q91="-",0,G91*I91) -> 0 | S91: =IF(G91>$N$1,$A91&"L"&S$1,"-") -> - | T91: =IF(S91="-","-",$A91) -> - | U91: =IF(T91="-","-","TerHea") -> - | V91: =IF(U91="-",0,9999) -> 0 | W91: =VLOOKUP(A91,[1]SummaryTable!$A$2:$F$359,4,FALSE) -> 65.3
A92: H131 | B92: =A92 -> H131 | C92: 20 | D92: 31 | E92: =VLOOKUP(A92,[1]SummaryTable!$A$2:$F$359,2,FALSE) -> 6688463.9 | F92: =VLOOKUP(A92,[1]SummaryTable!$A$2:$F$359,3,FALSE) -> 540832.81 | G92: =1.2*W92 -> 76.319892 | H92: =VLOOKUP(A92,[1]SummaryTable!$A$2:$F$359,5,FALSE) -> 0.79200282 | I92: =VLOOKUP(A92,[1]SummaryTable!$A$2:$F$359,6,FALSE) -> 0.20799718 | J92: =IF(I92>0.1,[2]Processes!$A$6,[2]Processes!$A$5) -> Heatpl | K92: =IF(G92>$N$1,$A92&"L"&K$1,"-") -> - | L92: =IF(K92="-","-",$A92) -> - | M92: =IF(L92="-","-","Heatpl") -> - | N92: =IF(M92="-",0,G92) -> 0 | O92: =IF(G92*I92>$N$1,$A92&"L"&O$1,"-") -> - | P92: =IF(O92="-","-",A92) -> - | Q92: =IF(P92="-","-","CHPpl_") -> - | R92: =IF(Q92="-",0,G92*I92) -> 0 | S92: =IF(G92>$N$1,$A92&"L"&S$1,"-") -> - | T92: =IF(S92="-","-",$A92) -> - | U92: =IF(T92="-","-","TerHea") -> - | V92: =IF(U92="-",0,9999) -> 0 | W92: =VLOOKUP(A92,[1]SummaryTable!$A$2:$F$359,4,FALSE) -> 63.59991
A93: H321 | B93: =A93 -> H321 | C93: 7 | D93: 21 | E93: =VLOOKUP(A93,[1]SummaryTable!$A$2:$F$359,2,FALSE) -> 6296442.3 | F93: =VLOOKUP(A93,[1]SummaryTable!$A$2:$F$359,3,FALSE) -> 435031.37 | G93: =1.2*W93 -> 75.024 | H93: =VLOOKUP(A93,[1]SummaryTable!$A$2:$F$359,5,FALSE) -> 0.88197726 | I93: =VLOOKUP(A93,[1]SummaryTable!$A$2:$F$359,6,FALSE) -> 0.11802274 | J93: =IF(I93>0.1,[2]Processes!$A$6,[2]Processes!$A$5) -> Heatpl | K93: =IF(G93>$N$1,$A93&"L"&K$1,"-") -> - | L93: =IF(K93="-","-",$A93) -> - | M93: =IF(L93="-","-","Heatpl") -> - | N93: =IF(M93="-",0,G93) -> 0 | O93: =IF(G93*I93>$N$1,$A93&"L"&O$1,"-") -> - | P93: =IF(O93="-","-",A93) -> - | Q93: =IF(P93="-","-","CHPpl_") -> - | R93: =IF(Q93="-",0,G93*I93) -> 0 | S93: =IF(G93>$N$1,$A93&"L"&S$1,"-") -> - | T93: =IF(S93="-","-",$A93) -> - | U93: =IF(T93="-","-","TerHea") -> - | V93: =IF(U93="-",0,9999) -> 0 | W93: =VLOOKUP(A93,[1]SummaryTable!$A$2:$F$359,4,FALSE) -> 62.52
A94: H347 | B94: =A94 -> H347 | C94: 12 | D94: 22 | E94: =VLOOKUP(A94,[1]SummaryTable!$A$2:$F$359,2,FALSE) -> 6212137.4 | F94: =VLOOKUP(A94,[1]SummaryTable!$A$2:$F$359,3,FALSE) -> 390477.74 | G94: =1.2*W94 -> 73.896 | H94: =VLOOKUP(A94,[1]SummaryTable!$A$2:$F$359,5,FALSE) -> 1 | I94: =VLOOKUP(A94,[1]SummaryTable!$A$2:$F$359,6,FALSE) -> 0 | J94: =IF(I94>0.1,[2]Processes!$A$6,[2]Processes!$A$5) -> Sawmal | K94: =IF(G94>$N$1,$A94&"L"&K$1,"-") -> - | L94: =IF(K94="-","-",$A94) -> - | M94: =IF(L94="-","-","Heatpl") -> - | N94: =IF(M94="-",0,G94) -> 0 | O94: =IF(G94*I94>$N$1,$A94&"L"&O$1,"-") -> - | P94: =IF(O94="-","-",A94) -> - | Q94: =IF(P94="-","-","CHPpl_") -> - | R94: =IF(Q94="-",0,G94*I94) -> 0 | S94: =IF(G94>$N$1,$A94&"L"&S$1,"-") -> - | T94: =IF(S94="-","-",$A94) -> - | U94: =IF(T94="-","-","TerHea") -> - | V94: =IF(U94="-",0,9999) -> 0 | W94: =VLOOKUP(A94,[1]SummaryTable!$A$2:$F$359,4,FALSE) -> 61.58
A95: H227 | B95: =A95 -> H227 | C95: 5 | D95: 12 | E95: =VLOOKUP(A95,[1]SummaryTable!$A$2:$F$359,2,FALSE) -> 6473956.1 | F95: =VLOOKUP(A95,[1]SummaryTable!$A$2:$F$359,3,FALSE) -> 538345.83 | G95: =1.2*W95 -> 72.48 | H95: =VLOOKUP(A95,[1]SummaryTable!$A$2:$F$359,5,FALSE) -> 0.60429463 | I95: =VLOOKUP(A95,[1]SummaryTable!$A$2:$F$359,6,FALSE) -> 0.39570537 | J95: =IF(I95>0.1,[2]Processes!$A$6,[2]Processes!$A$5) -> Heatpl | K95: =IF(G95>$N$1,$A95&"L"&K$1,"-") -> - | L95: =IF(K95="-","-",$A95) -> - | M95: =IF(L95="-","-","Heatpl") -> - | N95: =IF(M95="-",0,G95) -> 0 | O95: =IF(G95*I95>$N$1,$A95&"L"&O$1,"-") -> - | P95: =IF(O95="-","-",A95) -> - | Q95: =IF(P95="-","-","CHPpl_") -> - | R95: =IF(Q95="-",0,G95*I95) -> 0 | S95: =IF(G95>$N$1,$A95&"L"&S$1,"-") -> - | T95: =IF(S95="-","-",$A95) -> - | U95: =IF(T95="-","-","TerHea") -> - | V95: =IF(U95="-",0,9999) -> 0 | W95: =VLOOKUP(A95,[1]SummaryTable!$A$2:$F$359,4,FALSE) -> 60.4
A96: H299 | B96: =A96 -> H299 | C96: 6 | D96: 21 | E96: =VLOOKUP(A96,[1]SummaryTable!$A$2:$F$359,2,FALSE) -> 6359357.2 | F96: =VLOOKUP(A96,[1]SummaryTable!$A$2:$F$359,3,FALSE) -> 480048.91 | G96: =1.2*W96 -> 70.1724 | H96: =VLOOKUP(A96,[1]SummaryTable!$A$2:$F$359,5,FALSE) -> 1 | I96: =VLOOKUP(A96,[1]SummaryTable!$A$2:$F$359,6,FALSE) -> 0 | J96: =IF(I96>0.1,[2]Processes!$A$6,[2]Processes!$A$5) -> Sawmal | K96: =IF(G96>$N$1,$A96&"L"&K$1,"-") -> - | L96: =IF(K96="-","-",$A96) -> - | M96: =IF(L96="-","-","Heatpl") -> - | N96: =IF(M96="-",0,G96) -> 0 | O96: =IF(G96*I96>$N$1,$A96&"L"&O$1,"-") -> - | P96: =IF(O96="-","-",A96) -> - | Q96: =IF(P96="-","-","CHPpl_") -> - | R96: =IF(Q96="-",0,G96*I96) -> 0 | S96: =IF(G96>$N$1,$A96&"L"&S$1,"-") -> - | T96: =IF(S96="-","-",$A96) -> - | U96: =IF(T96="-","-","TerHea") -> - | V96: =IF(U96="-",0,9999) -> 0 | W96: =VLOOKUP(A96,[1]SummaryTable!$A$2:$F$359,4,FALSE) -> 58.477
A97: H356 | B97: =A97 -> H356 | C97: 12 | D97: 22 | E97: =VLOOKUP(A97,[1]SummaryTable!$A$2:$F$359,2,FALSE) -> 6154231.9 | F97: =VLOOKUP(A97,[1]SummaryTable!$A$2:$F$359,3,FALSE) -> 459316.29 | G97: =1.2*W97 -> 64.08 | H97: =VLOOKUP(A97,[1]SummaryTable!$A$2:$F$359,5,FALSE) -> 1 | I97: =VLOOKUP(A97,[1]SummaryTable!$A$2:$F$359,6,FALSE) -> 0 | J97: =IF(I97>0.1,[2]Processes!$A$6,[2]Processes!$A$5) -> Sawmal | K97: =IF(G97>$N$1,$A97&"L"&K$1,"-") -> - | L97: =IF(K97="-","-",$A97) -> - | M97: =IF(L97="-","-","Heatpl") -> - | N97: =IF(M97="-",0,G97) -> 0 | O97: =IF(G97*I97>$N$1,$A97&"L"&O$1,"-") -> - | P97: =IF(O97="-","-",A97) -> - | Q97: =IF(P97="-","-","CHPpl_") -> - | R97: =IF(Q97="-",0,G97*I97) -> 0 | S97: =IF(G97>$N$1,$A97&"L"&S$1,"-") -> - | T97: =IF(S97="-","-",$A97) -> - | U97: =IF(T97="-","-","TerHea") -> - | V97: =IF(U97="-",0,9999) -> 0 | W97: =VLOOKUP(A97,[1]SummaryTable!$A$2:$F$359,4,FALSE) -> 53.4
A98: H327 | B98: =A98 -> H327 | C98: 8 | D98: 21 | E98: =VLOOKUP(A98,[1]SummaryTable!$A$2:$F$359,2,FALSE) -> 6274174 | F98: =VLOOKUP(A98,[1]SummaryTable!$A$2:$F$359,3,FALSE) -> 533012.65 | G98: =1.2*W98 -> 63.72 | H98: =VLOOKUP(A98,[1]SummaryTable!$A$2:$F$359,5,FALSE) -> 1 | I98: =VLOOKUP(A98,[1]SummaryTable!$A$2:$F$359,6,FALSE) -> 0 | J98: =IF(I98>0.1,[2]Processes!$A$6,[2]Processes!$A$5) -> Sawmal | K98: =IF(G98>$N$1,$A98&"L"&K$1,"-") -> - | L98: =IF(K98="-","-",$A98) -> - | M98: =IF(L98="-","-","Heatpl") -> - | N98: =IF(M98="-",0,G98) -> 0 | O98: =IF(G98*I98>$N$1,$A98&"L"&O$1,"-") -> - | P98: =IF(O98="-","-",A98) -> - | Q98: =IF(P98="-","-","CHPpl_") -> - | R98: =IF(Q98="-",0,G98*I98) -> 0 | S98: =IF(G98>$N$1,$A98&"L"&S$1,"-") -> - | T98: =IF(S98="-","-",$A98) -> - | U98: =IF(T98="-","-","TerHea") -> - | V98: =IF(U98="-",0,9999) -> 0 | W98: =VLOOKUP(A98,[1]SummaryTable!$A$2:$F$359,4,FALSE) -> 53.1
A99: H141 | B99: =A99 -> H141 | C99: 17 | D99: 31 | E99: =VLOOKUP(A99,[1]SummaryTable!$A$2:$F$359,2,FALSE) -> 6656628.2 | F99: =VLOOKUP(A99,[1]SummaryTable!$A$2:$F$359,3,FALSE) -> 429620.09 | G99: =1.2*W99 -> 62.16 | H99: =VLOOKUP(A99,[1]SummaryTable!$A$2:$F$359,5,FALSE) -> 1 | I99: =VLOOKUP(A99,[1]SummaryTable!$A$2:$F$359,6,FALSE) -> 0 | J99: =IF(I99>0.1,[2]Processes!$A$6,[2]Processes!$A$5) -> Sawmal | K99: =IF(G99>$N$1,$A99&"L"&K$1,"-") -> - | L99: =IF(K99="-","-",$A99) -> - | M99: =IF(L99="-","-","Heatpl") -> - | N99: =IF(M99="-",0,G99) -> 0 | O99: =IF(G99*I99>$N$1,$A99&"L"&O$1,"-") -> - | P99: =IF(O99="-","-",A99) -> - | Q99: =IF(P99="-","-","CHPpl_") -> - | R99: =IF(Q99="-",0,G99*I99) -> 0 | S99: =IF(G99>$N$1,$A99&"L"&S$1,"-") -> - | T99: =IF(S99="-","-",$A99) -> - | U99: =IF(T99="-","-","TerHea") -> - | V99: =IF(U99="-",0,9999) -> 0 | W99: =VLOOKUP(A99,[1]SummaryTable!$A$2:$F$359,4,FALSE) -> 51.8
A100: H230 | B100: =A100 -> H230 | C100: 14 | D100: 23 | E100: =VLOOKUP(A100,[1]SummaryTable!$A$2:$F$359,2,FALSE) -> 6467420.8 | F100: =VLOOKUP(A100,[1]SummaryTable!$A$2:$F$359,3,FALSE) -> 321004.39 | G100: =1.2*W100 -> 61.272523 | H100: =VLOOKUP(A100,[1]SummaryTable!$A$2:$F$359,5,FALSE) -> 1 | I100: =VLOOKUP(A100,[1]SummaryTable!$A$2:$F$359,6,FALSE) -> 0 | J100: =IF(I100>0.1,[2]Processes!$A$6,[2]Processes!$A$5) -> Sawmal | K100: =IF(G100>$N$1,$A100&"L"&K$1,"-") -> - | L100: =IF(K100="-","-",$A100) -> - | M100: =IF(L100="-","-","Heatpl") -> - | N100: =IF(M100="-",0,G100) -> 0 | O100: =IF(G100*I100>$N$1,$A100&"L"&O$1,"-") -> - | P100: =IF(O100="-","-",A100) -> - | Q100: =IF(P100="-","-","CHPpl_") -> - | R100: =IF(Q100="-",0,G100*I100) -> 0 | S100: =IF(G100>$N$1,$A100&"L"&S$1,"-") -> - | T100: =IF(S100="-","-",$A100) -> - | U100: =IF(T100="-","-","TerHea") -> - | V100: =IF(U100="-",0,9999) -> 0 | W100: =VLOOKUP(A100,[1]SummaryTable!$A$2:$F$359,4,FALSE) -> 51.060436
A101: H202 | B101: =A101 -> H202 | C101: 4 | D101: 12 | E101: =VLOOKUP(A101,[1]SummaryTable!$A$2:$F$359,2,FALSE) -> 6539363.1 | F101: =VLOOKUP(A101,[1]SummaryTable!$A$2:$F$359,3,FALSE) -> 569401.83 | G101: =1.2*W101 -> 59.879952 | H101: =VLOOKUP(A101,[1]SummaryTable!$A$2:$F$359,5,FALSE) -> 0.92667489 | I101: =VLOOKUP(A101,[1]SummaryTable!$A$2:$F$359,6,FALSE) -> 0.073325106 | J101: =IF(I101>0.1,[2]Processes!$A$6,[2]Processes!$A$5) -> Sawmal | K101: =IF(G101>$N$1,$A101&"L"&K$1,"-") -> - | L101: =IF(K101="-","-",$A101) -> - | M101: =IF(L101="-","-","Heatpl") -> - | N101: =IF(M101="-",0,G101) -> 0 | O101: =IF(G101*I101>$N$1,$A101&"L"&O$1,"-") -> - | P101: =IF(O101="-","-",A101) -> - | Q101: =IF(P101="-","-","CHPpl_") -> - | R101: =IF(Q101="-",0,G101*I101) -> 0 | S101: =IF(G101>$N$1,$A101&"L"&S$1,"-") -> - | T101: =IF(S101="-","-",$A101) -> - | U101: =IF(T101="-","-","TerHea") -> - | V101: =IF(U101="-",0,9999) -> 0 | W101: =VLOOKUP(A101,[1]SummaryTable!$A$2:$F$359,4,FALSE) -> 49.89996
A102: H180 | B102: =A102 -> H180 | C102: 4 | D102: 12 | E102: =VLOOKUP(A102,[1]SummaryTable!$A$2:$F$359,2,FALSE) -> 6582933.1 | F102: =VLOOKUP(A102,[1]SummaryTable!$A$2:$F$359,3,FALSE) -> 615148.42 | G102: =1.2*W102 -> 59.61204 | H102: =VLOOKUP(A102,[1]SummaryTable!$A$2:$F$359,5,FALSE) -> 0.92862955 | I102: =VLOOKUP(A102,[1]SummaryTable!$A$2:$F$359,6,FALSE) -> 0.071370454 | J102: =IF(I102>0.1,[2]Processes!$A$6,[2]Processes!$A$5) -> Sawmal | K102: =IF(G102>$N$1,$A102&"L"&K$1,"-") -> - | L102: =IF(K102="-","-",$A102) -> - | M102: =IF(L102="-","-","Heatpl") -> - | N102: =IF(M102="-",0,G102) -> 0 | O102: =IF(G102*I102>$N$1,$A102&"L"&O$1,"-") -> - | P102: =IF(O102="-","-",A102) -> - | Q102: =IF(P102="-","-","CHPpl_") -> - | R102: =IF(Q102="-",0,G102*I102) -> 0 | S102: =IF(G102>$N$1,$A102&"L"&S$1,"-") -> - | T102: =IF(S102="-","-",$A102) -> - | U102: =IF(T102="-","-","TerHea") -> - | V102: =IF(U102="-",0,9999) -> 0 | W102: =VLOOKUP(A102,[1]SummaryTable!$A$2:$F$359,4,FALSE) -> 49.6767
... A360: H93 | B360: =A360 -> H93 | C360: 22 | D360: 12 | E360: =VLOOKUP(A360,[1]SummaryTable!$A$2:$F$359,2,FALSE) -> 6930823.5 | F360: =VLOOKUP(A360,[1]SummaryTable!$A$2:$F$359,3,FALSE) -> 620154.75 | G360: =1.2*W360 -> 0 | H360: =VLOOKUP(A360,[1]SummaryTable!$A$2:$F$359,5,FALSE) -> 0 | I360: =VLOOKUP(A360,[1]SummaryTable!$A$2:$F$359,6,FALSE) -> 1 | J360: =IF(I360>0.1,[2]Processes!$A$6,[2]Processes!$A$5) -> Heatpl | K360: =IF(G360>$N$1,$A360&"L"&K$1,"-") -> - | L360: =IF(K360="-","-",$A360) -> - | M360: =IF(L360="-","-","Heatpl") -> - | N360: =IF(M360="-",0,G360) -> 0 | O360: =IF(G360*I360>$N$1,$A360&"L"&O$1,"-") -> - | P360: =IF(O360="-","-",A360) -> - | Q360: =IF(P360="-","-","CHPpl_") -> - | R360: =IF(Q360="-",0,G360*I360) -> 0 | S360: =IF(G360>$N$1,$A360&"L"&S$1,"-") -> - | T360: =IF(S360="-","-",$A360) -> - | U360: =IF(T360="-","-","TerHea") -> - | V360: =IF(U360="-",0,9999) -> 0 | W360: =VLOOKUP(A360,[1]SummaryTable!$A$2:$F$359,4,FALSE) -> 0
F362: Tot | G362: =SUM(G3:G360) -> 31569.967
F363: CHP | G363: {=MMULT(TRANSPOSE(G3:G360),I3:I360)} -> 8228.3468 | N363: =SUM(N3:N360) -> 25037.048 | R363: =SUM(R3:R360) -> 17480.429 | W363: =SUM(W3:W360) -> 25957.089
F364: Tot > 40000 | G364: =SUMIFS(G3:G360,G3:G360,">40")/G362 -> 0.905541 | N364: =SUMIFS(N3:N360,N3:N360,">40")/N363 -> 1 | R364: =SUM(R4:R361) -> 14900.873
R365: =SUMIFS(R4:R361,R4:R361,">40")/R364 -> 1

Sheet SawMills
A1: Location | B1: Facility | C1: County | D1: NUTS2 | E1: GpsNorth | F1: GPSEast | G1: Production_sawn_wood_m3 | H1: 1 | I1: Type | J1: Capacity | K1: 2 | L1: Type | M1: Capacity | N1: 3 | O1: Type | P1: Capacity | Q1: 4 | R1: Type | S1: Capacity
A2: S103 | B2: =A2 -> S103 | C2: 23 | D2: 12 | E2: 7054802.8 | F2: 509821.01 | G2: 35 | H2: =IF(OR(G2>$G$165,I2="sawmbe"),$A2&"L"&H$1,"-") -> - | I2: sawmal | J2: =IF(H2="-",0,G2*J$164) -> 0 | K2: =IF(H2="-","-",$A2&"L"&K$1) -> - | L2: =IF(I2="sawmal","TerTal",IF(I2="sawmpi","TerTpi",IF(I2="sawmsp","TerTsp",""))) -> TerTal | M2: 9999 | N2: =IF(K2="-","-",$A2&"L"&N$1) -> - | O2: =IF(N2="-","-","TerHea") -> - | P2: 9999 | Q2: =IF(N2="-","-","-") -> - | R2: =IF(Q2="-","-","sawmbe") -> - | S2: =IF(Q2="-",0,MIN(G2*$J$164,1)) -> 0
A3: S104 | B3: =A3 -> S104 | C3: 6 | D3: 21 | E3: 6403975.7 | F3: 429989.62 | G3: 150 | H3: =IF(OR(G3>$G$165,I3="sawmbe"),$A3&"L"&H$1,"-") -> S104L1 | I3: sawmal | J3: =IF(H3="-",0,G3*J$164) -> 150 | K3: =IF(H3="-","-",$A3&"L"&K$1) -> S104L2 | L3: =IF(I3="sawmal","TerTal",IF(I3="sawmpi","TerTpi",IF(I3="sawmsp","TerTsp",""))) -> TerTal | M3: 9999 | N3: =IF(K3="-","-",$A3&"L"&N$1) -> S104L3 | O3: =IF(N3="-","-","TerHea") -> TerHea | P3: 9999 | Q3: =IF(N3="-","-","-") -> - | R3: =IF(Q3="-","-","sawmbe") -> - | S3: =IF(Q3="-",0,MIN(G3*$J$164,1)) -> 0
A4: S109 | B4: =A4 -> S109 | C4: 6 | D4: 21 | E4: 6365090.5 | F4: 504481.74 | G4: 110 | H4: =IF(OR(G4>$G$165,I4="sawmbe"),$A4&"L"&H$1,"-") -> S109L1 | I4: sawmal | J4: =IF(H4="-",0,G4*J$164) -> 110 | K4: =IF(H4="-","-",$A4&"L"&K$1) -> S109L2 | L4: =IF(I4="sawmal","TerTal",IF(I4="sawmpi","TerTpi",IF(I4="sawmsp","TerTsp",""))) -> TerTal | M4: 9999 | N4: =IF(K4="-","-",$A4&"L"&N$1) -> S109L3 | O4: =IF(N4="-","-","TerHea") -> TerHea | P4: 9999 | Q4: =IF(N4="-","-","-") -> - | R4: =IF(Q4="-","-","sawmbe") -> - | S4: =IF(Q4="-",0,MIN(G4*$J$164,1)) -> 0
A5: S11 | B5: =A5 -> S11 | C5: 8 | D5: 21 | E5: 6305533.6 | F5: 564851.98 | G5: 37.5 | H5: =IF(OR(G5>$G$165,I5="sawmbe"),$A5&"L"&H$1,"-") -> - | I5: sawmal | J5: =IF(H5="-",0,G5*J$164) -> 0 | K5: =IF(H5="-","-",$A5&"L"&K$1) -> - | L5: =IF(I5="sawmal","TerTal",IF(I5="sawmpi","TerTpi",IF(I5="sawmsp","TerTsp",""))) -> TerTal | M5: 9999 | N5: =IF(K5="-","-",$A5&"L"&N$1) -> - | O5: =IF(N5="-","-","TerHea") -> - | P5: 9999 | Q5: =IF(N5="-","-","-") -> - | R5: =IF(Q5="-","-","sawmbe") -> - | S5: =IF(Q5="-",0,MIN(G5*$J$164,1)) -> 0
A6: S113 | B6: =A6 -> S113 | C6: 22 | D6: 12 | E6: 6990964.9 | F6: 662430.51 | G6: 0 | H6: =IF(OR(G6>$G$165,I6="sawmbe"),$A6&"L"&H$1,"-") -> - | I6: sawmpi | J6: =IF(H6="-",0,G6*J$164) -> 0 | K6: =IF(H6="-","-",$A6&"L"&K$1) -> - | L6: =IF(I6="sawmal","TerTal",IF(I6="sawmpi","TerTpi",IF(I6="sawmsp","TerTsp",""))) -> TerTpi | M6: 9999 | N6: =IF(K6="-","-",$A6&"L"&N$1) -> - | O6: =IF(N6="-","-","TerHea") -> - | P6: 9999 | Q6: =IF(N6="-","-","-") -> - | R6: =IF(Q6="-","-","sawmbe") -> - | S6: =IF(Q6="-",0,MIN(G6*$J$164,1)) -> 0
A7: S114 | B7: =A7 -> S114 | C7: 19 | D7: 12 | E7: 6607316.1 | F7: 538703.64 | G7: 320 | H7: =IF(OR(G7>$G$165,I7="sawmbe"),$A7&"L"&H$1,"-") -> S114L1 | I7: sawmal | J7: =IF(H7="-",0,G7*J$164) -> 320 | K7: =IF(H7="-","-",$A7&"L"&K$1) -> S114L2 | L7: =IF(I7="sawmal","TerTal",IF(I7="sawmpi","TerTpi",IF(I7="sawmsp","TerTsp",""))) -> TerTal | M7: 9999 | N7: =IF(K7="-","-",$A7&"L"&N$1) -> S114L3 | O7: =IF(N7="-","-","TerHea") -> TerHea | P7: 9999 | Q7: =IF(N7="-","-","-") -> - | R7: =IF(Q7="-","-","sawmbe") -> - | S7: =IF(Q7="-",0,MIN(G7*$J$164,1)) -> 0
A8: S115 | B8: =A8 -> S115 | C8: 18 | D8: 12 | E8: 6550449.7 | F8: 480006.14 | G8: 0 | H8: =IF(OR(G8>$G$165,I8="sawmbe"),$A8&"L"&H$1,"-") -> - | I8: sawmsp | J8: =IF(H8="-",0,G8*J$164) -> 0 | K8: =IF(H8="-","-",$A8&"L"&K$1) -> - | L8: =IF(I8="sawmal","TerTal",IF(I8="sawmpi","TerTpi",IF(I8="sawmsp","TerTsp",""))) -> TerTsp | M8: 9999 | N8: =IF(K8="-","-",$A8&"L"&N$1) -> - | O8: =IF(N8="-","-","TerHea") -> - | P8: 9999 | Q8: =IF(N8="-","-","-") -> - | R8: =IF(Q8="-","-","sawmbe") -> - | S8: =IF(Q8="-",0,MIN(G8*$J$164,1)) -> 0
A9: S116 | B9: =A9 -> S116 | C9: 8 | D9: 21 | E9: 6283573.9 | F9: 535287.88 | G9: 100 | H9: =IF(OR(G9>$G$165,I9="sawmbe"),$A9&"L"&H$1,"-") -> S116L1 | I9: sawmal | J9: =IF(H9="-",0,G9*J$164) -> 100 | K9: =IF(H9="-","-",$A9&"L"&K$1) -> S116L2 | L9: =IF(I9="sawmal","TerTal",IF(I9="sawmpi","TerTpi",IF(I9="sawmsp","TerTsp",""))) -> TerTal | M9: 9999 | N9: =IF(K9="-","-",$A9&"L"&N$1) -> S116L3 | O9: =IF(N9="-","-","TerHea") -> TerHea | P9: 9999 | Q9: =IF(N9="-","-","-") -> - | R9: =IF(Q9="-","-","sawmbe") -> - | S9: =IF(Q9="-",0,MIN(G9*$J$164,1)) -> 0
A10: S12 | B10: =A10 -> S12 | C10: 25 | D10: 33 | E10: 7430157.7 | F10: 847565.1 | G10: 65 | H10: =IF(OR(G10>$G$165,I10="sawmbe"),$A10&"L"&H$1,"-") -> S12L1 | I10: sawmal | J10: =IF(H10="-",0,G10*J$164) -> 65 | K10: =IF(H10="-","-",$A10&"L"&K$1) -> S12L2 | L10: =IF(I10="sawmal","TerTal",IF(I10="sawmpi","TerTpi",IF(I10="sawmsp","TerTsp",""))) -> TerTal | M10: 9999 | N10: =IF(K10="-","-",$A10&"L"&N$1) -> S12L3 | O10: =IF(N10="-","-","TerHea") -> TerHea | P10: 9999 | Q10: =IF(N10="-","-","-") -> - | R10: =IF(Q10="-","-","sawmbe") -> - | S10: =IF(Q10="-",0,MIN(G10*$J$164,1)) -> 0
A11: S121 | B11: =A11 -> S121 | C11: 23 | D11: 12 | E11: 6962674.1 | F11: 473192.35 | G11: 340 | H11: =IF(OR(G11>$G$165,I11="sawmbe"),$A11&"L"&H$1,"-") -> S121L1 | I11: sawmsp | J11: =IF(H11="-",0,G11*J$164) -> 340 | K11: =IF(H11="-","-",$A11&"L"&K$1) -> S121L2 | L11: =IF(I11="sawmal","TerTal",IF(I11="sawmpi","TerTpi",IF(I11="sawmsp","TerTsp",""))) -> TerTsp | M11: 9999 | N11: =IF(K11="-","-",$A11&"L"&N$1) -> S121L3 | O11: =IF(N11="-","-","TerHea") -> TerHea | P11: 9999 | Q11: =IF(N11="-","-","-") -> - | R11: =IF(Q11="-","-","sawmbe") -> - | S11: =IF(Q11="-",0,MIN(G11*$J$164,1)) -> 0
A12: S124 | B12: =A12 -> S124 | C12: 20 | D12: 31 | E12: 6779532.8 | F12: 454078.18 | G12: 125 | H12: =IF(OR(G12>$G$165,I12="sawmbe"),$A12&"L"&H$1,"-") -> S124L1 | I12: sawmal | J12: =IF(H12="-",0,G12*J$164) -> 125 | K12: =IF(H12="-","-",$A12&"L"&K$1) -> S124L2 | L12: =IF(I12="sawmal","TerTal",IF(I12="sawmpi","TerTpi",IF(I12="sawmsp","TerTsp",""))) -> TerTal | M12: 9999 | N12: =IF(K12="-","-",$A12&"L"&N$1) -> S124L3 | O12: =IF(N12="-","-","TerHea") -> TerHea | P12: 9999 | Q12: =IF(N12="-","-","-") -> - | R12: =IF(Q12="-","-","sawmbe") -> - | S12: =IF(Q12="-",0,MIN(G12*$J$164,1)) -> 0
A13: S125 | B13: =A13 -> S125 | C13: 19 | D13: 12 | E13: 6599957.5 | F13: 563410.66 | G13: 550 | H13: =IF(OR(G13>$G$165,I13="sawmbe"),$A13&"L"&H$1,"-") -> S125L1 | I13: sawmsp | J13: =IF(H13="-",0,G13*J$164) -> 550 | K13: =IF(H13="-","-",$A13&"L"&K$1) -> S125L2 | L13: =IF(I13="sawmal","TerTal",IF(I13="sawmpi","TerTpi",IF(I13="sawmsp","TerTsp",""))) -> TerTsp | M13: 9999 | N13: =IF(K13="-","-",$A13&"L"&N$1) -> S125L3 | O13: =IF(N13="-","-","TerHea") -> TerHea | P13: 9999 | Q13: =IF(N13="-","-","-") -> - | R13: =IF(Q13="-","-","sawmbe") -> - | S13: =IF(Q13="-",0,MIN(G13*$J$164,1)) -> 0
... A28: S180 | B28: =A28 -> S180 | C28: 23 | D28: 12 | E28: 6975217.5 | F28: 511698.52 | G28: 60 | H28: =IF(OR(G28>$G$165,I28="sawmbe"),$A28&"L"&H$1,"-") -> S180L1 | I28: sawmal | J28: =IF(H28="-",0,G28*J$164) -> 60 | K28: =IF(H28="-","-",$A28&"L"&K$1) -> S180L2 | L28: =IF(I28="sawmal","TerTal",IF(I28="sawmpi","TerTpi",IF(I28="sawmsp","TerTsp",""))) -> TerTal | M28: 9999 | N28: =IF(K28="-","-",$A28&"L"&N$1) -> S180L3 | O28: =IF(N28="-","-","TerHea") -> TerHea | P28: 9999 | Q28: =IF(N28="-","-","-") -> - | R28: =IF(Q28="-","-","sawmbe") -> - | S28: =IF(Q28="-",0,MIN(G28*$J$164,1)) -> 0
A29: S181 | B29: =A29 -> S181 | C29: 8 | D29: 21 | E29: 6299599.3 | F29: 545401.97 | G29: 190 | H29: =IF(OR(G29>$G$165,I29="sawmbe"),$A29&"L"&H$1,"-") -> S181L1 | I29: sawmsp | J29: =IF(H29="-",0,G29*J$164) -> 190 | K29: =IF(H29="-","-",$A29&"L"&K$1) -> S181L2 | L29: =IF(I29="sawmal","TerTal",IF(I29="sawmpi","TerTpi",IF(I29="sawmsp","TerTsp",""))) -> TerTsp | M29: 9999 | N29: =IF(K29="-","-",$A29&"L"&N$1) -> S181L3 | O29: =IF(N29="-","-","TerHea") -> TerHea | P29: 9999 | Q29: =IF(N29="-","-",$A29&"L"&Q$1) -> S181L4 | R29: =IF(Q29="-","-","sawmbe") -> sawmbe | S29: =IF(Q29="-",0,MIN(G29*$J$164,1)) -> 1
A30: S187 | B30: =A30 -> S187 | C30: 5 | D30: 12 | E30: 6454634.1 | F30: 504968.9 | G30: 37.5 | H30: =IF(OR(G30>$G$165,I30="sawmbe"),$A30&"L"&H$1,"-") -> - | I30: sawmal | J30: =IF(H30="-",0,G30*J$164) -> 0 | K30: =IF(H30="-","-",$A30&"L"&K$1) -> - | L30: =IF(I30="sawmal","TerTal",IF(I30="sawmpi","TerTpi",IF(I30="sawmsp","TerTsp",""))) -> TerTal | M30: 9999 | N30: =IF(K30="-","-",$A30&"L"&N$1) -> - | O30: =IF(N30="-","-","TerHea") -> - | P30: 9999 | Q30: =IF(N30="-","-","-") -> - | R30: =IF(Q30="-","-","sawmbe") -> - | S30: =IF(Q30="-",0,MIN(G30*$J$164,1)) -> 0
A31: S192 | B31: =A31 -> S192 | C31: 17 | D31: 31 | E31: 6728093.6 | F31: 387542.06 | G31: 420 | H31: =IF(OR(G31>$G$165,I31="sawmbe"),$A31&"L"&H$1,"-") -> S192L1 | I31: sawmal | J31: =IF(H31="-",0,G31*J$164) -> 420 | K31: =IF(H31="-","-",$A31&"L"&K$1) -> S192L2 | L31: =IF(I31="sawmal","TerTal",IF(I31="sawmpi","TerTpi",IF(I31="sawmsp","TerTsp",""))) -> TerTal | M31: 9999 | N31: =IF(K31="-","-",$A31&"L"&N$1) -> S192L3 | O31: =IF(N31="-","-","TerHea") -> TerHea | P31: 9999 | Q31: =IF(N31="-","-","-") -> - | R31: =IF(Q31="-","-","sawmbe") -> - | S31: =IF(Q31="-",0,MIN(G31*$J$164,1)) -> 0
A32: S194 | B32: =A32 -> S194 | C32: 6 | D32: 21 | E32: 6352250.3 | F32: 526377.45 | G32: 400 | H32: =IF(OR(G32>$G$165,I32="sawmbe"),$A32&"L"&H$1,"-") -> S194L1 | I32: sawmsp | J32: =IF(H32="-",0,G32*J$164) -> 400 | K32: =IF(H32="-","-",$A32&"L"&K$1) -> S194L2 | L32: =IF(I32="sawmal","TerTal",IF(I32="sawmpi","TerTpi",IF(I32="sawmsp","TerTsp",""))) -> TerTsp | M32: 9999 | N32: =IF(K32="-","-",$A32&"L"&N$1) -> S194L3 | O32: =IF(N32="-","-","TerHea") -> TerHea | P32: 9999 | Q32: =IF(N32="-","-","-") -> - | R32: =IF(Q32="-","-","sawmbe") -> - | S32: =IF(Q32="-",0,MIN(G32*$J$164,1)) -> 0
A33: S197 | B33: =A33 -> S197 | C33: 13 | D33: 23 | E33: 6303731.2 | F33: 359156.57 | G33: 144 | H33: =IF(OR(G33>$G$165,I33="sawmbe"),$A33&"L"&H$1,"-") -> S197L1 | I33: sawmpi | J33: =IF(H33="-",0,G33*J$164) -> 144 | K33: =IF(H33="-","-",$A33&"L"&K$1) -> S197L2 | L33: =IF(I33="sawmal","TerTal",IF(I33="sawmpi","TerTpi",IF(I33="sawmsp","TerTsp",""))) -> TerTpi | M33: 9999 | N33: =IF(K33="-","-",$A33&"L"&N$1) -> S197L3 | O33: =IF(N33="-","-","TerHea") -> TerHea | P33: 9999 | Q33: =IF(N33="-","-","-") -> - | R33: =IF(Q33="-","-","sawmbe") -> - | S33: =IF(Q33="-",0,MIN(G33*$J$164,1)) -> 0
A34: S200 | B34: =A34 -> S200 | C34: 6 | D34: 21 | E34: 6369930.5 | F34: 502059.63 | G34: 125 | H34: =IF(OR(G34>$G$165,I34="sawmbe"),$A34&"L"&H$1,"-") -> S200L1 | I34: sawmal | J34: =IF(H34="-",0,G34*J$164) -> 125 | K34: =IF(H34="-","-",$A34&"L"&K$1) -> S200L2 | L34: =IF(I34="sawmal","TerTal",IF(I34="sawmpi","TerTpi",IF(I34="sawmsp","TerTsp",""))) -> TerTal | M34: 9999 | N34: =IF(K34="-","-",$A34&"L"&N$1) -> S200L3 | O34: =IF(N34="-","-","TerHea") -> TerHea | P34: 9999 | Q34: =IF(N34="-","-","-") -> - | R34: =IF(Q34="-","-","sawmbe") -> - | S34: =IF(Q34="-",0,MIN(G34*$J$164,1)) -> 0
A35: S202 | B35: =A35 -> S202 | C35: 19 | D35: 12 | E35: 6633090.1 | F35: 538195.8 | G35: 55 | H35: =IF(OR(G35>$G$165,I35="sawmbe"),$A35&"L"&H$1,"-") -> S202L1 | I35: sawmpi | J35: =IF(H35="-",0,G35*J$164) -> 55 | K35: =IF(H35="-","-",$A35&"L"&K$1) -> S202L2 | L35: =IF(I35="sawmal","TerTal",IF(I35="sawmpi","TerTpi",IF(I35="sawmsp","TerTsp",""))) -> TerTpi | M35: 9999 | N35: =IF(K35="-","-",$A35&"L"&N$1) -> S202L3 | O35: =IF(N35="-","-","TerHea") -> TerHea | P35: 9999 | Q35: =IF(N35="-","-","-") -> - | R35: =IF(Q35="-","-","sawmbe") -> - | S35: =IF(Q35="-",0,MIN(G35*$J$164,1)) -> 0
A36: S203 | B36: =A36 -> S203 | C36: 24 | D36: 33 | E36: 7054087.1 | F36: 717882.08 | G36: 0 | H36: =IF(OR(G36>$G$165,I36="sawmbe"),$A36&"L"&H$1,"-") -> - | I36: sawmpi | J36: =IF(H36="-",0,G36*J$164) -> 0 | K36: =IF(H36="-","-",$A36&"L"&K$1) -> - | L36: =IF(I36="sawmal","TerTal",IF(I36="sawmpi","TerTpi",IF(I36="sawmsp","TerTsp",""))) -> TerTpi | M36: 9999 | N36: =IF(K36="-","-",$A36&"L"&N$1) -> - | O36: =IF(N36="-","-","TerHea") -> - | P36: 9999 | Q36: =IF(N36="-","-","-") -> - | R36: =IF(Q36="-","-","sawmbe") -> - | S36: =IF(Q36="-",0,MIN(G36*$J$164,1)) -> 0
A37: S207 | B37: =A37 -> S207 | C37: 14 | D37: 23 | E37: 6558431 | F37: 317960.37 | G37: 45 | H37: =IF(OR(G37>$G$165,I37="sawmbe"),$A37&"L"&H$1,"-") -> - | I37: sawmal | J37: =IF(H37="-",0,G37*J$164) -> 0 | K37: =IF(H37="-","-",$A37&"L"&K$1) -> - | L37: =IF(I37="sawmal","TerTal",IF(I37="sawmpi","TerTpi",IF(I37="sawmsp","TerTsp",""))) -> TerTal | M37: 9999 | N37: =IF(K37="-","-",$A37&"L"&N$1) -> - | O37: =IF(N37="-","-","TerHea") -> - | P37: 9999 | Q37: =IF(N37="-","-","-") -> - | R37: =IF(Q37="-","-","sawmbe") -> - | S37: =IF(Q37="-",0,MIN(G37*$J$164,1)) -> 0
A38: S214 | B38: =A38 -> S214 | C38: 20 | D38: 31 | E38: 6781524.6 | F38: 507134.63 | G38: 30 | H38: =IF(OR(G38>$G$165,I38="sawmbe"),$A38&"L"&H$1,"-") -> - | I38: sawmal | J38: =IF(H38="-",0,G38*J$164) -> 0 | K38: =IF(H38="-","-",$A38&"L"&K$1) -> - | L38: =IF(I38="sawmal","TerTal",IF(I38="sawmpi","TerTpi",IF(I38="sawmsp","TerTsp",""))) -> TerTal | M38: 9999 | N38: =IF(K38="-","-",$A38&"L"&N$1) -> - | O38: =IF(N38="-","-","TerHea") -> - | P38: 9999 | Q38: =IF(N38="-","-","-") -> - | R38: =IF(Q38="-","-","sawmbe") -> - | S38: =IF(Q38="-",0,MIN(G38*$J$164,1)) -> 0
A39: S216 | B39: =A39 -> S216 | C39: 17 | D39: 31 | E39: 6585612 | F39: 398726.4 | G39: 270 | H39: =IF(OR(G39>$G$165,I39="sawmbe"),$A39&"L"&H$1,"-") -> S216L1 | I39: sawmpi | J39: =IF(H39="-",0,G39*J$164) -> 270 | K39: =IF(H39="-","-",$A39&"L"&K$1) -> S216L2 | L39: =IF(I39="sawmal","TerTal",IF(I39="sawmpi","TerTpi",IF(I39="sawmsp","TerTsp",""))) -> TerTpi | M39: 9999 | N39: =IF(K39="-","-",$A39&"L"&N$1) -> S216L3 | O39: =IF(N39="-","-","TerHea") -> TerHea | P39: 9999 | Q39: =IF(N39="-","-",$A39&"L"&Q$1) -> S216L4 | R39: =IF(Q39="-","-","sawmbe") -> sawmbe | S39: =IF(Q39="-",0,MIN(G39*$J$164,1)) -> 1
A40: S220 | B40: =A40 -> S220 | C40: 8 | D40: 21 | E40: 6336608.2 | F40: 562274.67 | G40: 331 | H40: =IF(OR(G40>$G$165,I40="sawmbe"),$A40&"L"&H$1,"-") -> S220L1 | I40: sawmpi | J40: =IF(H40="-",0,G40*J$164) -> 331 | K40: =IF(H40="-","-",$A40&"L"&K$1) -> S220L2 | L40: =IF(I40="sawmal","TerTal",IF(I40="sawmpi","TerTpi",IF(I40="sawmsp","TerTsp",""))) -> TerTpi | M40: 9999 | N40: =IF(K40="-","-",$A40&"L"&N$1) -> S220L3 | O40: =IF(N40="-","-","TerHea") -> TerHea | P40: 9999 | Q40: =IF(N40="-","-","-") -> - | R40: =IF(Q40="-","-","sawmbe") -> - | S40: =IF(Q40="-",0,MIN(G40*$J$164,1)) -> 0
A41: S227 | B41: =A41 -> S227 | C41: 24 | D41: 33 | E41: 7075853.4 | F41: 764249.66 | G41: 60 | H41: =IF(OR(G41>$G$165,I41="sawmbe"),$A41&"L"&H$1,"-") -> S227L1 | I41: sawmsp | J41: =IF(H41="-",0,G41*J$164) -> 60 | K41: =IF(H41="-","-",$A41&"L"&K$1) -> S227L2 | L41: =IF(I41="sawmal","TerTal",IF(I41="sawmpi","TerTpi",IF(I41="sawmsp","TerTsp",""))) -> TerTsp | M41: 9999 | N41: =IF(K41="-","-",$A41&"L"&N$1) -> S227L3 | O41: =IF(N41="-","-","TerHea") -> TerHea | P41: 9999 | Q41: =IF(N41="-","-","-") -> - | R41: =IF(Q41="-","-","sawmbe") -> - | S41: =IF(Q41="-",0,MIN(G41*$J$164,1)) -> 0
A42: S231 | B42: =A42 -> S231 | C42: 20 | D42: 31 | E42: 6727997.5 | F42: 505567.33 | G42: 80 | H42: =IF(OR(G42>$G$165,I42="sawmbe"),$A42&"L"&H$1,"-") -> S231L1 | I42: sawmpi | J42: =IF(H42="-",0,G42*J$164) -> 80 | K42: =IF(H42="-","-",$A42&"L"&K$1) -> S231L2 | L42: =IF(I42="sawmal","TerTal",IF(I42="sawmpi","TerTpi",IF(I42="sawmsp","TerTsp",""))) -> TerTpi | M42: 9999 | N42: =IF(K42="-","-",$A42&"L"&N$1) -> S231L3 | O42: =IF(N42="-","-","TerHea") -> TerHea | P42: 9999 | Q42: =IF(N42="-","-","-") -> - | R42: =IF(Q42="-","-","sawmbe") -> - | S42: =IF(Q42="-",0,MIN(G42*$J$164,1)) -> 0
A43: S232 | B43: =A43 -> S232 | C43: 17 | D43: 31 | E43: 6633071.1 | F43: 339758.16 | G43: 100 | H43: =IF(OR(G43>$G$165,I43="sawmbe"),$A43&"L"&H$1,"-") -> S232L1 | I43: sawmal | J43: =IF(H43="-",0,G43*J$164) -> 100 | K43: =IF(H43="-","-",$A43&"L"&K$1) -> S232L2 | L43: =IF(I43="sawmal","TerTal",IF(I43="sawmpi","TerTpi",IF(I43="sawmsp","TerTsp",""))) -> TerTal | M43: 9999 | N43: =IF(K43="-","-",$A43&"L"&N$1) -> S232L3 | O43: =IF(N43="-","-","TerHea") -> TerHea | P43: 9999 | Q43: =IF(N43="-","-","-") -> - | R43: =IF(Q43="-","-","sawmbe") -> - | S43: =IF(Q43="-",0,MIN(G43*$J$164,1)) -> 0
A44: S239 | B44: =A44 -> S239 | C44: 7 | D44: 21 | E44: 6322427.9 | F44: 473971.27 | G44: 0 | H44: =IF(OR(G44>$G$165,I44="sawmbe"),$A44&"L"&H$1,"-") -> - | I44: sawmpi | J44: =IF(H44="-",0,G44*J$164) -> 0 | K44: =IF(H44="-","-",$A44&"L"&K$1) -> - | L44: =IF(I44="sawmal","TerTal",IF(I44="sawmpi","TerTpi",IF(I44="sawmsp","TerTsp",""))) -> TerTpi | M44: 9999 | N44: =IF(K44="-","-",$A44&"L"&N$1) -> - | O44: =IF(N44="-","-","TerHea") -> - | P44: 9999 | Q44: =IF(N44="-","-","-") -> - | R44: =IF(Q44="-","-","sawmbe") -> - | S44: =IF(Q44="-",0,MIN(G44*$J$164,1)) -> 0
A45: S244 | B45: =A45 -> S244 | C45: 6 | D45: 21 | E45: 6356980 | F45: 445458.92 | G45: 70 | H45: =IF(OR(G45>$G$165,I45="sawmbe"),$A45&"L"&H$1,"-") -> S244L1 | I45: sawmal | J45: =IF(H45="-",0,G45*J$164) -> 70 | K45: =IF(H45="-","-",$A45&"L"&K$1) -> S244L2 | L45: =IF(I45="sawmal","TerTal",IF(I45="sawmpi","TerTpi",IF(I45="sawmsp","TerTsp",""))) -> TerTal | M45: 9999 | N45: =IF(K45="-","-",$A45&"L"&N$1) -> S244L3 | O45: =IF(N45="-","-","TerHea") -> TerHea | P45: 9999 | Q45: =IF(N45="-","-","-") -> - | R45: =IF(Q45="-","-","sawmbe") -> - | S45: =IF(Q45="-",0,MIN(G45*$J$164,1)) -> 0
A46: S245 | B46: =A46 -> S245 | C46: 9 | D46: 21 | E46: 6364089.5 | F46: 694100.5 | G46: 60 | H46: =IF(OR(G46>$G$165,I46="sawmbe"),$A46&"L"&H$1,"-") -> S245L1 | I46: sawmal | J46: =IF(H46="-",0,G46*J$164) -> 60 | K46: =IF(H46="-","-",$A46&"L"&K$1) -> S245L2 | L46: =IF(I46="sawmal","TerTal",IF(I46="sawmpi","TerTpi",IF(I46="sawmsp","TerTsp",""))) -> TerTal | M46: 9999 | N46: =IF(K46="-","-",$A46&"L"&N$1) -> S245L3 | O46: =IF(N46="-","-","TerHea") -> TerHea | P46: 9999 | Q46: =IF(N46="-","-","-") -> - | R46: =IF(Q46="-","-","sawmbe") -> - | S46: =IF(Q46="-",0,MIN(G46*$J$164,1)) -> 0
A47: S248 | B47: =A47 -> S248 | C47: 17 | D47: 31 | E47: 6667634.1 | F47: 388532.68 | G47: 0 | H47: =IF(OR(G47>$G$165,I47="sawmbe"),$A47&"L"&H$1,"-") -> - | I47: sawmal | J47: =IF(H47="-",0,G47*J$164) -> 0 | K47: =IF(H47="-","-",$A47&"L"&K$1) -> - | L47: =IF(I47="sawmal","TerTal",IF(I47="sawmpi","TerTpi",IF(I47="sawmsp","TerTsp",""))) -> TerTal | M47: 9999 | N47: =IF(K47="-","-",$A47&"L"&N$1) -> - | O47: =IF(N47="-","-","TerHea") -> - | P47: 9999 | Q47: =IF(N47="-","-","-") -> - | R47: =IF(Q47="-","-","sawmbe") -> - | S47: =IF(Q47="-",0,MIN(G47*$J$164,1)) -> 0
A48: S249 | B48: =A48 -> S249 | C48: 22 | D48: 12 | E48: 6932175.4 | F48: 550828.42 | G48: 250 | H48: =IF(OR(G48>$G$165,I48="sawmbe"),$A48&"L"&H$1,"-") -> S249L1 | I48: sawmal | J48: =IF(H48="-",0,G48*J$164) -> 250 | K48: =IF(H48="-","-",$A48&"L"&K$1) -> S249L2 | L48: =IF(I48="sawmal","TerTal",IF(I48="sawmpi","TerTpi",IF(I48="sawmsp","TerTsp",""))) -> TerTal | M48: 9999 | N48: =IF(K48="-","-",$A48&"L"&N$1) -> S249L3 | O48: =IF(N48="-","-","TerHea") -> TerHea | P48: 9999 | Q48: =IF(N48="-","-",$A48&"L"&Q$1) -> S249L4 | R48: =IF(Q48="-","-","sawmbe") -> sawmbe | S48: =IF(Q48="-",0,MIN(G48*$J$164,1)) -> 1
A49: S252 | B49: =A49 -> S252 | C49: 21 | D49: 31 | E49: 6729992 | F49: 622988.99 | G49: 38 | H49: =IF(OR(G49>$G$165,I49="sawmbe"),$A49&"L"&H$1,"-") -> - | I49: sawmal | J49: =IF(H49="-",0,G49*J$164) -> 0 | K49: =IF(H49="-","-",$A49&"L"&K$1) -> - | L49: =IF(I49="sawmal","TerTal",IF(I49="sawmpi","TerTpi",IF(I49="sawmsp","TerTsp",""))) -> TerTal | M49: 9999 | N49: =IF(K49="-","-",$A49&"L"&N$1) -> - | O49: =IF(N49="-","-","TerHea") -> - | P49: 9999 | Q49: =IF(N49="-","-","-") -> - | R49: =IF(Q49="-","-","sawmbe") -> - | S49: =IF(Q49="-",0,MIN(G49*$J$164,1)) -> 0
A50: S254 | B50: =A50 -> S254 | C50: 23 | D50: 12 | E50: 7021940.6 | F50: 472228.64 | G50: 65 | H50: =IF(OR(G50>$G$165,I50="sawmbe"),$A50&"L"&H$1,"-") -> S254L1 | I50: sawmal | J50: =IF(H50="-",0,G50*J$164) -> 65 | K50: =IF(H50="-","-",$A50&"L"&K$1) -> S254L2 | L50: =IF(I50="sawmal","TerTal",IF(I50="sawmpi","TerTpi",IF(I50="sawmsp","TerTsp",""))) -> TerTal | M50: 9999 | N50: =IF(K50="-","-",$A50&"L"&N$1) -> S254L3 | O50: =IF(N50="-","-","TerHea") -> TerHea | P50: 9999 | Q50: =IF(N50="-","-","-") -> - | R50: =IF(Q50="-","-","sawmbe") -> - | S50: =IF(Q50="-",0,MIN(G50*$J$164,1)) -> 0
A51: S255 | B51: =A51 -> S255 | C51: 6 | D51: 21 | E51: 6343774.7 | F51: 474292.36 | G51: 145 | H51: =IF(OR(G51>$G$165,I51="sawmbe"),$A51&"L"&H$1,"-") -> S255L1 | I51: sawmal | J51: =IF(H51="-",0,G51*J$164) -> 145 | K51: =IF(H51="-","-",$A51&"L"&K$1) -> S255L2 | L51: =IF(I51="sawmal","TerTal",IF(I51="sawmpi","TerTpi",IF(I51="sawmsp","TerTsp",""))) -> TerTal | M51: 9999 | N51: =IF(K51="-","-",$A51&"L"&N$1) -> S255L3 | O51: =IF(N51="-","-","TerHea") -> TerHea | P51: 9999 | Q51: =IF(N51="-","-",$A51&"L"&Q$1) -> S255L4 | R51: =IF(Q51="-","-","sawmbe") -> sawmbe | S51: =IF(Q51="-",0,MIN(G51*$J$164,1)) -> 1
A52: S259 | B52: =A52 -> S259 | C52: 20 | D52: 31 | E52: 6666434.8 | F52: 567102 | G52: 85 | H52: =IF(OR(G52>$G$165,I52="sawmbe"),$A52&"L"&H$1,"-") -> S259L1 | I52: sawmsp | J52: =IF(H52="-",0,G52*J$164) -> 85 | K52: =IF(H52="-","-",$A52&"L"&K$1) -> S259L2 | L52: =IF(I52="sawmal","TerTal",IF(I52="sawmpi","TerTpi",IF(I52="sawmsp","TerTsp",""))) -> TerTsp | M52: 9999 | N52: =IF(K52="-","-",$A52&"L"&N$1) -> S259L3 | O52: =IF(N52="-","-","TerHea") -> TerHea | P52: 9999 | Q52: =IF(N52="-","-","-") -> - | R52: =IF(Q52="-","-","sawmbe") -> - | S52: =IF(Q52="-",0,MIN(G52*$J$164,1)) -> 0
A53: S263 | B53: =A53 -> S263 | C53: 24 | D53: 33 | E53: 7104254.2 | F53: 730935.88 | G53: 590 | H53: =IF(OR(G53>$G$165,I53="sawmbe"),$A53&"L"&H$1,"-") -> S263L1 | I53: sawmal | J53: =IF(H53="-",0,G53*J$164) -> 590 | K53: =IF(H53="-","-",$A53&"L"&K$1) -> S263L2 | L53: =IF(I53="sawmal","TerTal",IF(I53="sawmpi","TerTpi",IF(I53="sawmsp","TerTsp",""))) -> TerTal | M53: 9999 | N53: =IF(K53="-","-",$A53&"L"&N$1) -> S263L3 | O53: =IF(N53="-","-","TerHea") -> TerHea | P53: 9999 | Q53: =IF(N53="-","-",$A53&"L"&Q$1) -> S263L4 | R53: =IF(Q53="-","-","sawmbe") -> sawmbe | S53: =IF(Q53="-",0,MIN(G53*$J$164,1)) -> 1
A54: S265 | B54: =A54 -> S265 | C54: 8 | D54: 21 | E54: 6271114.8 | F54: 527180.92 | G54: 220 | H54: =IF(OR(G54>$G$165,I54="sawmbe"),$A54&"L"&H$1,"-") -> S265L1 | I54: sawmpi | J54: =IF(H54="-",0,G54*J$164) -> 220 | K54: =IF(H54="-","-",$A54&"L"&K$1) -> S265L2 | L54: =IF(I54="sawmal","TerTal",IF(I54="sawmpi","TerTpi",IF(I54="sawmsp","TerTsp",""))) -> TerTpi | M54: 9999 | N54: =IF(K54="-","-",$A54&"L"&N$1) -> S265L3 | O54: =IF(N54="-","-","TerHea") -> TerHea | P54: 9999 | Q54: =IF(N54="-","-","-") -> - | R54: =IF(Q54="-","-","sawmbe") -> - | S54: =IF(Q54="-",0,MIN(G54*$J$164,1)) -> 0
...

Sheet PulpPaper
A1: ID | B1: County | C1: NUTS2 | D1: GpsNorth | E1: GPSEast | F1: Company | G1: Location | H1: Skogsindustrierna (ej: Domsjö) | I1: 1 | J1: Type | K1: Capacity | L1: 2 | M1: Type | N1: Capacity | O1: 3 | P1: Type | Q1: Capacity | R1: 4 | S1: Type | T1: Capacity | U1: 5 | V1: Type | W1: Capacity | X1: 6 | Y1: Type | Z1: Capacity | AA1: 7 | AB1: Type | AC1: Capacity
A2: P2 | B2: 25 | C2: 33 | D2: 7322422.7 | E2: 877545.97 | F2: BillerudKorsnäs | G2: Karlsborg | H2: Papper: Säck, MF kraftpapper Massa: Sulfat marknadsmassa, Integrerad sulfat | I2: =$A2&"L"&I$1 -> P2L1 | J2: PuChem | K2: 335 | L2: =$A2&"L"&L$1 -> P2L2 | M2: PaChem | N2: 335 | O2: =$A2&"L"&O$1 -> P2L3 | P2: FTDpl_ | Q2: 1 | R2: =$A2&"L"&R$1 -> P2L4 | S2: PaBCCS | T2: 0 | U2: =$A2&"L"&U$1 -> P2L5 | V2: =IF(OR($J2="Puchem",$J2="PuDiss",$M2="Puchem",$M2="PuDiss",$P2="Puchem",$P2="PuDiss"),"TerPal","-") -> TerPal | W2: 9999 | X2: =$A2&"L"&X$1 -> P2L6 | Y2: =IF(OR($J2="PuMech",$J2="PuCTMP",$M2="PuMech",$M2="PuCTMP",$P2="PuMech",$P2="PuCTMP"),"TerSpr",IF(OR($J2="FTDpl_",$M2="FTDpl_",$P2="FTDpl_",$S2="FTDpl_"),"TerHea","-")) -> TerHea | Z2: 9999 | AA2: =$A2&"L"&AA$1 -> P2L7 | AB2: - | AC2: 0
A3: P26 | B3: 25 | C3: 33 | D3: 7258723 | E3: 799508.1 | F3: Smurfit Kappa | G3: Piteå | H3: Papper: Kraftliner Massa: Integrerad sulfat | I3: =$A3&"L"&I$1 -> P26L1 | J3: PuChem | K3: 700 | L3: =$A3&"L"&L$1 -> P26L2 | M3: PaChem | N3: 700 | O3: =$A3&"L"&O$1 -> P26L3 | P3: - | Q3: 0 | R3: =$A3&"L"&R$1 -> P26L4 | S3: PaBCCS | T3: 0 | U3: =$A3&"L"&U$1 -> P26L5 | V3: =IF(OR($J3="Puchem",$J3="PuDiss",$M3="Puchem",$M3="PuDiss",$P3="Puchem",$P3="PuDiss"),"TerPal","-") -> TerPal | W3: 9999 | X3: =$A3&"L"&X$1 -> P26L6 | Y3: =IF(OR($J3="PuMech",$J3="PuCTMP",$M3="PuMech",$M3="PuCTMP",$P3="PuMech",$P3="PuCTMP"),"TerSpr",IF(OR($J3="FTDpl_",$M3="FTDpl_",$P3="FTDpl_",$S3="FTDpl_"),"TerHea","-")) -> - | Z3: 9999 | AA3: =$A3&"L"&AA$1 -> P26L7 | AB3: - | AC3: 0
A4: P24 | B4: 25 | C4: 33 | D4: 7254302.6 | E4: 803084.55 | F4: SCA | G4: Munksund | H4: Papper: Kraftliner Massa: Integrerad sulfat | I4: =$A4&"L"&I$1 -> P24L1 | J4: PuChem | K4: 300 | L4: =$A4&"L"&L$1 -> P24L2 | M4: PaChem | N4: 300 | O4: =$A4&"L"&O$1 -> P24L3 | P4: - | Q4: 1 | R4: =$A4&"L"&R$1 -> P24L4 | S4: PaBCCS | T4: 0 | U4: =$A4&"L"&U$1 -> P24L5 | V4: =IF(OR($J4="Puchem",$J4="PuDiss",$M4="Puchem",$M4="PuDiss",$P4="Puchem",$P4="PuDiss"),"TerPal","-") -> TerPal | W4: 9999 | X4: =$A4&"L"&X$1 -> P24L6 | Y4: =IF(OR($J4="PuMech",$J4="PuCTMP",$M4="PuMech",$M4="PuCTMP",$P4="PuMech",$P4="PuCTMP"),"TerSpr",IF(OR($J4="FTDpl_",$M4="FTDpl_",$P4="FTDpl_",$S4="FTDpl_"),"TerHea","-")) -> - | Z4: 9999 | AA4: =$A4&"L"&AA$1 -> P24L7 | AB4: - | AC4: 0
A5: P25 | B5: 24 | C5: 33 | D5: 7074566 | E5: 762640.16 | F5: SCA | G5: Obbola | H5: Papper: Kraftliner, Testliner Massa: Integrerad sulfat | I5: =$A5&"L"&I$1 -> P25L1 | J5: PuChem | K5: 725 | L5: =$A5&"L"&L$1 -> P25L2 | M5: PaChem | N5: 725 | O5: =$A5&"L"&O$1 -> P25L3 | P5: PuDiss | Q5: 0 | R5: =$A5&"L"&R$1 -> P25L4 | S5: FTDpl_ | T5: 1 | U5: =$A5&"L"&U$1 -> P25L5 | V5: =IF(OR($J5="Puchem",$J5="PuDiss",$M5="Puchem",$M5="PuDiss",$P5="Puchem",$P5="PuDiss"),"TerPal","-") -> TerPal | W5: 9999 | X5: =$A5&"L"&X$1 -> P25L6 | Y5: =IF(OR($J5="PuMech",$J5="PuCTMP",$M5="PuMech",$M5="PuCTMP",$P5="PuMech",$P5="PuCTMP"),"TerSpr",IF(OR($J5="FTDpl_",$M5="FTDpl_",$P5="FTDpl_",$S5="FTDpl_"),"TerHea","-")) -> TerHea | Z5: 9999 | AA5: =$A5&"L"&AA$1 -> P25L7 | AB5: - | AC5: 0
A6: P13 | B6: 22 | C6: 12 | D6: 7028224.1 | E6: 708365.21 | F6: M-real Sverige AB | I6: =$A6&"L"&I$1 -> P13L1 | J6: PuChem | K6: 0 | L6: =$A6&"L"&L$1 -> P13L2 | M6: - | N6: 0 | O6: =$A6&"L"&O$1 -> P13L3 | P6: - | Q6: 0 | R6: =$A6&"L"&R$1 -> P13L4 | S6: - | T6: 0 | U6: =$A6&"L"&U$1 -> P13L5 | V6: =IF(OR($J6="Puchem",$J6="PuDiss",$M6="Puchem",$M6="PuDiss",$P6="Puchem",$P6="PuDiss"),"TerPal","-") -> TerPal | W6: 9999 | X6: =$A6&"L"&X$1 -> P13L6 | Y6: =IF(OR($J6="PuMech",$J6="PuCTMP",$M6="PuMech",$M6="PuCTMP",$P6="PuMech",$P6="PuCTMP"),"TerSpr",IF(OR($J6="FTDpl_",$M6="FTDpl_",$P6="FTDpl_",$S6="FTDpl_"),"TerHea","-")) -> - | Z6: 9999 | AA6: =$A6&"L"&AA$1 -> P13L7 | AB6: - | AC6: 0
A7: P4 | B7: 22 | C7: 12 | D7: 7020950.6 | E7: 685571.37 | F7: Domsjö Fabriker AB | G7: Domsjö | H7: Massa: Dissolving (cellulosa, lignin och bioetanol) | I7: =$A7&"L"&I$1 -> P4L1 | J7: PuDiss | K7: 260 | L7: =$A7&"L"&L$1 -> P4L2 | M7: - | N7: 0 | O7: =$A7&"L"&O$1 -> P4L3 | P7: - | Q7: 0 | R7: =$A7&"L"&R$1 -> P4L4 | S7: - | T7: 0 | U7: =$A7&"L"&U$1 -> P4L5 | V7: =IF(OR($J7="Puchem",$J7="PuDiss",$M7="Puchem",$M7="PuDiss",$P7="Puchem",$P7="PuDiss"),"TerPal","-") -> TerPal | W7: 9999 | X7: =$A7&"L"&X$1 -> P4L6 | Y7: =IF(OR($J7="PuMech",$J7="PuCTMP",$M7="PuMech",$M7="PuCTMP",$P7="PuMech",$P7="PuCTMP"),"TerSpr",IF(OR($J7="FTDpl_",$M7="FTDpl_",$P7="FTDpl_",$S7="FTDpl_"),"TerHea","-")) -> - | Z7: 9999 | AA7: =$A7&"L"&AA$1 -> P4L7 | AB7: - | AC7: 0
A8: P35 | B8: 22 | C8: 12 | D8: 6991891 | E8: 702513 | F8: Metsä Board | G8: Husum | H8: Papper: Kraftliner, Övrig kartong Massa: Sulfat marknadsmassa, Integrerad sulfat | I8: =$A8&"L"&I$1 -> P35L1 | J8: PuChem | K8: 650 | L8: =$A8&"L"&L$1 -> P35L2 | M8: PaChem | N8: 650 | O8: =$A8&"L"&O$1 -> P35L3 | P8: - | Q8: 0 | R8: =$A8&"L"&R$1 -> P35L4 | S8: PaBCCS | T8: 0 | U8: =$A8&"L"&U$1 -> P35L5 | V8: =IF(OR($J8="Puchem",$J8="PuDiss",$M8="Puchem",$M8="PuDiss",$P8="Puchem",$P8="PuDiss"),"TerPal","-") -> TerPal | W8: 9999 | X8: =$A8&"L"&X$1 -> P35L6 | Y8: =IF(OR($J8="PuMech",$J8="PuCTMP",$M8="PuMech",$M8="PuCTMP",$P8="PuMech",$P8="PuCTMP"),"TerSpr",IF(OR($J8="FTDpl_",$M8="FTDpl_",$P8="FTDpl_",$S8="FTDpl_"),"TerHea","-")) -> - | Z8: 9999 | AA8: =$A8&"L"&AA$1 -> P35L7 | AB8: - | AC8: 0
A9: P12 | B9: 22 | C9: 12 | D9: 6987738.9 | E9: 635881.6 | F9: Mondi | G9: Dynäs | H9: Papper: Säck, MF kraftpapper Massa: Integrerad sulfat | I9: =$A9&"L"&I$1 -> P12L1 | J9: PuChem | K9: 225 | L9: =$A9&"L"&L$1 -> P12L2 | M9: PaChem | N9: 225 | O9: =$A9&"L"&O$1 -> P12L3 | P9: - | Q9: 0 | R9: =$A9&"L"&R$1 -> P12L4 | S9: PaBCCS | T9: 0 | U9: =$A9&"L"&U$1 -> P12L5 | V9: =IF(OR($J9="Puchem",$J9="PuDiss",$M9="Puchem",$M9="PuDiss",$P9="Puchem",$P9="PuDiss"),"TerPal","-") -> TerPal | W9: 9999 | X9: =$A9&"L"&X$1 -> P12L6 | Y9: =IF(OR($J9="PuMech",$J9="PuCTMP",$M9="PuMech",$M9="PuCTMP",$P9="PuMech",$P9="PuCTMP"),"TerSpr",IF(OR($J9="FTDpl_",$M9="FTDpl_",$P9="FTDpl_",$S9="FTDpl_"),"TerHea","-")) -> - | Z9: 9999 | AA9: =$A9&"L"&AA$1 -> P12L7 | AB9: - | AC9: 0
A10: P22 | B10: 22 | C10: 12 | D10: 6929243.4 | E10: 619204.25 | F10: SCA | G10: Östrand | H10: Massa: Sulfat marknadsmassa, Mekanisk marknadsmassa (CTMP) | I10: =$A10&"L"&I$1 -> P22L1 | J10: PuChem | K10: 900 | L10: =$A10&"L"&L$1 -> P22L2 | M10: OtChem | N10: 225 | O10: =$A10&"L"&O$1 -> P22L3 | P10: PuCTMP | Q10: 100 | R10: =$A10&"L"&R$1 -> P22L4 | S10: PuBCCS | T10: 0 | U10: =$A10&"L"&U$1 -> P22L5 | V10: =IF(OR($J10="Puchem",$J10="PuDiss",$M10="Puchem",$M10="PuDiss",$P10="Puchem",$P10="PuDiss"),"TerPal","-") -> TerPal | W10: 9999 | X10: =$A10&"L"&X$1 -> P22L6 | Y10: =IF(OR($J10="PuMech",$J10="PuCTMP",$M10="PuMech",$M10="PuCTMP",$P10="PuMech",$P10="PuCTMP"),"TerSpr",IF(OR($J10="FTDpl_",$M10="FTDpl_",$P10="FTDpl_",$S10="FTDpl_"),"TerHea","-")) -> TerSpr | Z10: 9999 | AA10: =$A10&"L"&AA$1 -> P22L7 | AB10: - | AC10: 0
A11: P23 | B11: 22 | C11: 12 | D11: 6920247.6 | E11: 622009.73 | F11: SCA | G11: Ortviken | H11: Papper: Tidningspapper, SC/LWC Massa: Integrerad mekanisk | I11: =$A11&"L"&I$1 -> P23L1 | J11: PuDiss | K11: 0 | L11: =$A11&"L"&L$1 -> P23L2 | M11: - | N11: 0 | O11: =$A11&"L"&O$1 -> P23L3 | P11: - | Q11: 0 | R11: =$A11&"L"&R$1 -> P23L4 | S11: FTDpl_ | T11: 1 | U11: =$A11&"L"&U$1 -> P23L5 | V11: =IF(OR($J11="Puchem",$J11="PuDiss",$M11="Puchem",$M11="PuDiss",$P11="Puchem",$P11="PuDiss"),"TerPal","-") -> TerPal | W11: 9999 | X11: =$A11&"L"&X$1 -> P23L6 | Y11: =IF(OR($J11="PuMech",$J11="PuCTMP",$M11="PuMech",$M11="PuCTMP",$P11="PuMech",$P11="PuCTMP"),"TerSpr",IF(OR($J11="FTDpl_",$M11="FTDpl_",$P11="FTDpl_",$S11="FTDpl_"),"TerHea","-")) -> TerHea | Z11: 9999 | AA11: =$A11&"L"&AA$1 -> P23L7 | AB11: - | AC11: 0
A12: P7 | B12: 21 | C12: 31 | D12: 6835953.3 | E12: 610650.91 | F12: Holmen | G12: Iggesund | H12: Papper: Sulfatkartong Massa: Sulfat marknadsmassa, Integrerad sulfat | I12: =$A12&"L"&I$1 -> P7L1 | J12: PuChem | K12: 540 | L12: =$A12&"L"&L$1 -> P7L2 | M12: PaChem | N12: 540 | O12: =$A12&"L"&O$1 -> P7L3 | P12: - | Q12: 0 | R12: =$A12&"L"&R$1 -> P7L4 | S12: PaBCCS | T12: 0 | U12: =$A12&"L"&U$1 -> P7L5 | V12: =IF(OR($J12="Puchem",$J12="PuDiss",$M12="Puchem",$M12="PuDiss",$P12="Puchem",$P12="PuDiss"),"TerPal","-") -> TerPal | W12: 9999 | X12: =$A12&"L"&X$1 -> P7L6 | Y12: =IF(OR($J12="PuMech",$J12="PuCTMP",$M12="PuMech",$M12="PuCTMP",$P12="PuMech",$P12="PuCTMP"),"TerSpr",IF(OR($J12="FTDpl_",$M12="FTDpl_",$P12="FTDpl_",$S12="FTDpl_"),"TerHea","-")) -> - | Z12: 9999 | AA12: =$A12&"L"&AA$1 -> P7L7 | AB12: - | AC12: 0
